Workbook
Name a: '[1]Param (DINN)'!$B$10
Name a: '[1]Param (DINN)'!$B$10
Name a: '[1]Param (DINN)'!$B$10
Name a: 'Param (DINN)'!$B$10
Name b: '[1]Param (DINN)'!$B$11
Name b: '[1]Param (DINN)'!$B$11
Name b: '[1]Param (DINN)'!$B$11
Name b: 'Param (DINN)'!$B$11
Name b12I: '[1]Param (DINN)'!$B$7
Name b12I: '[1]Param (DINN)'!$B$7
Name b12I: '[1]Param (DINN)'!$B$7
Name b12I: 'Param (DINN)'!$B$7
Name b12I1: '[1]Param (No DINN)'!$B$7
Name b12I1: '[1]Param (No DINN)'!$B$7
Name b12I1: '[1]Param (No DINN)'!$B$7
Name b12I1: 'Param (No DINN)'!$B$7
Name b12R: '[1]Param (DINN)'!$B$9
Name b12R: '[1]Param (DINN)'!$B$9
Name b12R: '[1]Param (DINN)'!$B$9
Name b12R: 'Param (DINN)'!$B$9
Name b12R1: '[1]Param (No DINN)'!$B$9
Name b12R1: '[1]Param (No DINN)'!$B$9
Name b12R1: '[1]Param (No DINN)'!$B$9
Name b12R1: 'Param (No DINN)'!$B$9
Name b12S: '[1]Param (DINN)'!$B$5
Name b12S: '[1]Param (DINN)'!$B$5
Name b12S: '[1]Param (DINN)'!$B$5
Name b12S: 'Param (DINN)'!$B$5
Name b12S1: '[1]Param (No DINN)'!$B$5
Name b12S1: '[1]Param (No DINN)'!$B$5
Name b12S1: '[1]Param (No DINN)'!$B$5
Name b12S1: 'Param (No DINN)'!$B$5
Name N: 'SIR Data (60 Days)'!$J$1
Name N: '[1]SIR Data (14 Days)'!$I$1
Name N: '[1]SIR Data (14 Days)'!$I$1
Name N: '[1]SIR Data (14 Days)'!$I$1
Name N: 'SIR Data (14 Days)'!$I$1
Name w12I: '[1]Param (DINN)'!$B$6
Name w12I: '[1]Param (DINN)'!$B$6
Name w12I: '[1]Param (DINN)'!$B$6
Name w12I: 'Param (DINN)'!$B$6
Name w12I1: '[1]Param (No DINN)'!$B$6
Name w12I1: '[1]Param (No DINN)'!$B$6
Name w12I1: '[1]Param (No DINN)'!$B$6
Name w12I1: 'Param (No DINN)'!$B$6
Name w12R: '[1]Param (DINN)'!$B$8
Name w12R: '[1]Param (DINN)'!$B$8
Name w12R: '[1]Param (DINN)'!$B$8
Name w12R: 'Param (DINN)'!$B$8
Name w12R1: '[1]Param (No DINN)'!$B$8
Name w12R1: '[1]Param (No DINN)'!$B$8
Name w12R1: '[1]Param (No DINN)'!$B$8
Name w12R1: 'Param (No DINN)'!$B$8
Name w12S: '[1]Param (DINN)'!$B$4
Name w12S: '[1]Param (DINN)'!$B$4
Name w12S: '[1]Param (DINN)'!$B$4
Name w12S: 'Param (DINN)'!$B$4
Name w12S1: '[1]Param (No DINN)'!$B$4
Name w12S1: '[1]Param (No DINN)'!$B$4
Name w12S1: '[1]Param (No DINN)'!$B$4

Sheet SIR_with 1 Neuron
A1: Neural Network Table | S1: Neural Network Table Formulas | W1: Error-Log Table
A2: Input | B2: Neuron and Output | G2: Real Data/1000 | J2: NN Error | N2: Parameters Table | P2: Error-Log Table | S2: Formulas for first day
A3: Day | B3: 1st Neuron | C3: Act.Func | D3: S_predicted | E3: I_predicted | F3: R_predicted | G3: S_data | H3: I_data | I3: R_data | J3: MSE | L3: Hidden Layer | M3: Name | N3: Parameter | O3: Value (optimal) | P3: MSE sum | Q3: =SUM(J4:J63) -> 0.050739321 | S3: Name | T3: Cell | U3: Formula | W3: Name | X3: Cell | Y3: Formula
A4: 0 | B4: =$O$4*A4+$O$5 -> -3.8828749 | C4: =1/(1+EXP(-B4)) -> 0.020176085 | D4: =$O$6*C4+$O$7 -> 0.97406531 | E4: =$O$8*C4+$O$9 -> 0.1503224 | F4: =$O$10*C4+$O$11 -> -0.12349642 | G4: 0.99916903 | H4: -0.00051644142 | I4: 0.0012964653 | J4: =SUM((D4-G4)^2,(E4-H4)^2,(F4-I4)^2)/60 -> 0.00064926359 | K4: =SUM((E4-H4)^2,(F4-I4)^2,(G4-J4)^2)/60 -> 0.017256122 | L4: 1st Neuron | M4: weight | N4: w | O4: 0.21339894 | S4: 1st Neuron | T4: B4 | U4: =$O$4*A4+$O$5 | W4: MSE | X4: P2 | Y4: =_xlfn.FORMULATEXT(Q3) -> =SUM(J4:J63)
A5: 1 | B5: =$O$4*A5+$O$5 -> -3.6694759 | C5: =1/(1+EXP(-B5)) -> 0.024856243 | D5: =$O$6*C5+$O$7 -> 0.96919309 | E5: =$O$8*C5+$O$9 -> 0.15082303 | F5: =$O$10*C5+$O$11 -> -0.11912766 | G5: 0.98960194 | H5: 0.0021639113 | I5: 0.002694591 | J5: =SUM((D5-G5)^2,(E5-H5)^2,(F5-I5)^2)/60 -> 0.0006226119 | M5: bias | N5: b | O5: -3.8828749 | S5: Act.Function | T5: C4 | U5: =TANH(B4)
A6: 2 | B6: =$O$4*A6+$O$5 -> -3.456077 | C6: =1/(1+EXP(-B6)) -> 0.030588146 | D6: =$O$6*C6+$O$7 -> 0.96322598 | E6: =$O$8*C6+$O$9 -> 0.15143616 | F6: =$O$10*C6+$O$11 -> -0.11377714 | G6: 1.0027007 | H6: 0.0033100596 | I6: -0.0047185297 | J6: =SUM((D6-G6)^2,(E6-H6)^2,(F6-I6)^2)/60 -> 0.00058988954 | L6: Output for 1st | M6: S_weight | N6: w_S | O6: -1.041036 | S6: S_predicted | T6: D4 | U6: =$O$6*C4+$O$7
A7: 3 | B7: =$O$4*A7+$O$5 -> -3.2426781 | C7: =1/(1+EXP(-B7)) -> 0.037590884 | D7: =$O$6*C7+$O$7 -> 0.95593587 | E7: =$O$8*C7+$O$9 -> 0.15218523 | F7: =$O$10*C7+$O$11 -> -0.10724033 | G7: 0.99110329 | H7: 0.0015165638 | I7: 0.0024789689 | J7: =SUM((D7-G7)^2,(E7-H7)^2,(F7-I7)^2)/60 -> 0.000599602 | M7: S_bias | N7: b_S | O7: 0.99506934 | S7: I_predicted | T7: E4 | U7: =$O$8*C4+$O$9
A8: 4 | B8: =$O$4*A8+$O$5 -> -3.0292791 | C8: =1/(1+EXP(-B8)) -> 0.046120531 | D8: =$O$6*C8+$O$7 -> 0.94705621 | E8: =$O$8*C8+$O$9 -> 0.15309763 | F8: =$O$10*C8+$O$11 -> -0.09927822 | G8: 0.99855053 | H8: 0.0020051112 | I8: 0.0038636349 | J8: =SUM((D8-G8)^2,(E8-H8)^2,(F8-I8)^2)/60 -> 0.00060198097 | M8: I_weight | N8: w_I | O8: 0.10696838 | S8: R_predicted | T8: F4 | U8: =$O$10*C4+$O$11
A9: 5 | B9: =$O$4*A9+$O$5 -> -2.8158802 | C9: =1/(1+EXP(-B9)) -> 0.056472049 | D9: =$O$6*C9+$O$7 -> 0.9362799 | E9: =$O$8*C9+$O$9 -> 0.15420492 | F9: =$O$10*C9+$O$11 -> -0.089615454 | G9: 0.99334815 | H9: 0.0057859344 | I9: -0.0046798608 | J9: =SUM((D9-G9)^2,(E9-H9)^2,(F9-I9)^2)/60 -> 0.00054165058 | M9: I_bias | N9: b_I | O9: 0.14816419 | S9: MSE | T9: J4 | U9: =SUM((D4-G4)^2,(E4-H4)^2,(F4-I4)^2)/60
A10: 6 | B10: =$O$4*A10+$O$5 -> -2.6024812 | C10: =1/(1+EXP(-B10)) -> 0.068978902 | D10: =$O$6*C10+$O$7 -> 0.92325982 | E10: =$O$8*C10+$O$9 -> 0.15554276 | F10: =$O$10*C10+$O$11 -> -0.077940762 | G10: 0.98283074 | H10: 0.012651331 | I10: 0.0030346095 | J10: =SUM((D10-G10)^2,(E10-H10)^2,(F10-I10)^2)/60 -> 0.00050872774 | M10: R_weight | N10: w_R | O10: 0.93346361
A11: 7 | B11: =$O$4*A11+$O$5 -> -2.3890823 | C11: =1/(1+EXP(-B11)) -> 0.084009022 | D11: =$O$6*C11+$O$7 -> 0.90761292 | E11: =$O$8*C11+$O$9 -> 0.1571505 | F11: =$O$10*C11+$O$11 -> -0.063910691 | G11: 0.97539399 | H11: 0.020354 | I11: 0.007466831 | J11: =SUM((D11-G11)^2,(E11-H11)^2,(F11-I11)^2)/60 -> 0.00047337178 | M11: R_bias | N11: b_R | O11: -0.14233006
A12: 8 | B12: =$O$4*A12+$O$5 -> -2.1756834 | C12: =1/(1+EXP(-B12)) -> 0.10195548 | D12: =$O$6*C12+$O$7 -> 0.88893001 | E12: =$O$8*C12+$O$9 -> 0.15907021 | F12: =$O$10*C12+$O$11 -> -0.047158324 | G12: 0.96249141 | H12: 0.033533967 | I12: 0.0091761695 | J12: =SUM((D12-G12)^2,(E12-H12)^2,(F12-I12)^2)/60 -> 0.00040573669
A13: 9 | B13: =$O$4*A13+$O$5 -> -1.9622844 | C13: =1/(1+EXP(-B13)) -> 0.12322003 | D13: =$O$6*C13+$O$7 -> 0.86679285 | E13: =$O$8*C13+$O$9 -> 0.16134484 | F13: =$O$10*C13+$O$11 -> -0.027308641 | G13: 0.94450237 | H13: 0.047496166 | I13: 0.007522534 | J13: =SUM((D13-G13)^2,(E13-H13)^2,(F13-I13)^2)/60 -> 0.00033689168
A14: 10 | B14: =$O$4*A14+$O$5 -> -1.7488855 | C14: =1/(1+EXP(-B14)) -> 0.14818782 | D14: =$O$6*C14+$O$7 -> 0.84080048 | E14: =$O$8*C14+$O$9 -> 0.16401561 | F14: =$O$10*C14+$O$11 -> -0.0040021149 | G14: 0.91819898 | H14: 0.067597221 | I14: 0.0032927993 | J14: =SUM((D14-G14)^2,(E14-H14)^2,(F14-I14)^2)/60 -> 0.0002556708
A15: 11 | B15: =$O$4*A15+$O$5 -> -1.5354866 | C15: =1/(1+EXP(-B15)) -> 0.17719235 | D15: =$O$6*C15+$O$7 -> 0.81060572 | E15: =$O$8*C15+$O$9 -> 0.16711817 | F15: =$O$10*C15+$O$11 -> 0.023072558 | G15: 0.89021614 | H15: 0.095969398 | I15: 0.019651499 | J15: =SUM((D15-G15)^2,(E15-H15)^2,(F15-I15)^2)/60 -> 0.0001901945
A16: 12 | B16: =$O$4*A16+$O$5 -> -1.3220876 | C16: =1/(1+EXP(-B16)) -> 0.21047118 | D16: =$O$6*C16+$O$7 -> 0.77596127 | E16: =$O$8*C16+$O$9 -> 0.17067795 | F16: =$O$10*C16+$O$11 -> 0.054137128 | G16: 0.83105635 | H16: 0.13982037 | I16: 0.024532806 | J16: =SUM((D16-G16)^2,(E16-H16)^2,(F16-I16)^2)/60 -> 8.1067893e-05
A17: 13 | B17: =$O$4*A17+$O$5 -> -1.1086887 | C17: =1/(1+EXP(-B17)) -> 0.24811544 | D17: =$O$6*C17+$O$7 -> 0.73677224 | E17: =$O$8*C17+$O$9 -> 0.1747047 | F17: =$O$10*C17+$O$11 -> 0.089276677 | G17: 0.77338802 | H17: 0.1957633 | I17: 0.038447975 | J17: =SUM((D17-G17)^2,(E17-H17)^2,(F17-I17)^2)/60 -> 7.2795614e-05
A18: 14 | B18: =$O$4*A18+$O$5 -> -0.89528975 | C18: =1/(1+EXP(-B18)) -> 0.29001942 | D18: =$O$6*C18+$O$7 -> 0.6931487 | E18: =$O$8*C18+$O$9 -> 0.1791871 | F18: =$O$10*C18+$O$11 -> 0.12839252 | G18: 0.68790871 | H18: 0.25894601 | I18: 0.063388111 | J18: =SUM((D18-G18)^2,(E18-H18)^2,(F18-I18)^2)/60 -> 0.00017690857
A19: 15 | B19: =$O$4*A19+$O$5 -> -0.68189081 | C19: =1/(1+EXP(-B19)) -> 0.33583942 | D19: =$O$6*C19+$O$7 -> 0.64544842 | E19: =$O$8*C19+$O$9 -> 0.18408839 | F19: =$O$10*C19+$O$11 -> 0.17116383 | G19: 0.59497832 | H19: 0.33076846 | I19: 0.073720662 | J19: =SUM((D19-G19)^2,(E19-H19)^2,(F19-I19)^2)/60 -> 0.00055929071
A20: 16 | B20: =$O$4*A20+$O$5 -> -0.46849187 | C20: =1/(1+EXP(-B20)) -> 0.38497326 | D20: =$O$6*C20+$O$7 -> 0.59429833 | E20: =$O$8*C20+$O$9 -> 0.18934416 | F20: =$O$10*C20+$O$11 -> 0.21702847 | G20: 0.48898601 | H20: 0.4078998 | I20: 0.099755418 | J20: =SUM((D20-G20)^2,(E20-H20)^2,(F20-I20)^2)/60 -> 0.0012101704
A21: 17 | B21: =$O$4*A21+$O$5 -> -0.25509294 | C21: =1/(1+EXP(-B21)) -> 0.43657035 | D21: =$O$6*C21+$O$7 -> 0.5405839 | E21: =$O$8*C21+$O$9 -> 0.19486342 | F21: =$O$10*C21+$O$11 -> 0.26519248 | G21: 0.39651124 | H21: 0.47372643 | I21: 0.13353312 | J21: =SUM((D21-G21)^2,(E21-H21)^2,(F21-I21)^2)/60 -> 0.0019309283
A22: 18 | B22: =$O$4*A22+$O$5 -> -0.041694 | C22: =1/(1+EXP(-B22)) -> 0.48957801 | D22: =$O$6*C22+$O$7 -> 0.48540102 | E22: =$O$8*C22+$O$9 -> 0.20053356 | F22: =$O$10*C22+$O$11 -> 0.3146732 | G22: 0.31251276 | H22: 0.52750319 | I22: 0.17173201 | J22: =SUM((D22-G22)^2,(E22-H22)^2,(F22-I22)^2)/60 -> 0.002620528
A23: 19 | B23: =$O$4*A23+$O$5 -> 0.17170494 | C23: =1/(1+EXP(-B23)) -> 0.54282108 | D23: =$O$6*C23+$O$7 -> 0.42997307 | E23: =$O$8*C23+$O$9 -> 0.20622888 | F23: =$O$10*C23+$O$11 -> 0.36437367 | G23: 0.23552071 | H23: 0.55793615 | I23: 0.20873749 | J23: =SUM((D23-G23)^2,(E23-H23)^2,(F23-I23)^2)/60 -> 0.003095539
... A63: 59 | B63: =$O$4*A63+$O$5 -> 8.7076624 | C63: =1/(1+EXP(-B63)) -> 0.99983471 | D63: =$O$6*C63+$O$7 -> -0.045794552 | E63: =$O$8*C63+$O$9 -> 0.25511489 | F63: =$O$10*C63+$O$11 -> 0.79097927 | G63: -0.00010788248 | H63: 0.053596926 | I63: 0.94100736 | J63: =SUM((D63-G63)^2,(E63-H63)^2,(F63-I63)^2)/60 -> 0.0010867532

Sheet SIR_with 2 Neurons
A1: Day | B1: 1st Neuron | C1: Act.Func N1 | D1: S1_predicted | E1: I1_predicted | F1: R1_predicted | G1: 2nd Neuron | H1: Act.Func N2 | I1: S2_predicted | J1: I2_predicted | K1: R2_predicted | L1: (S1 + S2)_pred | M1: (I1+I2)_pred | N1: (R1+R2)_ pred | O1: S data | P1: I data | Q1: R data | R1: MSE | S1: Hidden Layer | T1: Parameter | U1: Value | W1: MSE sum | X1: =SUM(R2:R61) -> 0.0049430427
A2: 0 | B2: =$U$2*A2+$U$3 -> 6.260022 | C2: =1/(1+EXP(-B2)) -> 0.99809244 | D2: =$U$4*C2+$U$5 -> 2.0849886 | E2: =$U$6*C2+$U$7 -> 1.9761976 | F2: =$U$6*C2+$U$7 -> 1.9761976 | G2: =$U$10*A2+$U$11 -> -4.2053171 | H2: =TANH(G2) -> -0.99955512 | I2: =$U$12*H2+$U$13 -> -1.0818186 | J2: =$U$14*H2+$U$15 -> -1.9082433 | K2: =$U$16*H2+$U$17 -> -2.0490433 | L2: =SUM(D2,I2) -> 1.0031701 | M2: =SUM(E2,J2) -> 0.067954357 | N2: =SUM(F2,K2) -> -0.072845646 | O2: 0.99916903 | P2: -0.00051644142 | Q2: 0.0012964653 | R2: =SUM((L2-O2)^2, (M2-P2)^2, (N2-Q2)^2)/60 -> 0.00017002185 | S2: 1st Neuron | T2: w11 | U2: -0.39494341 | V2: -0.45404349 | X2: 8.238e-05
A3: 1 | B3: =$U$2*A3+$U$3 -> 5.8650786 | C3: =1/(1+EXP(-B3)) -> 0.99717122 | D3: =$U$4*C3+$U$5 -> 2.0840799 | E3: =$U$6*C3+$U$7 -> 1.9766537 | F3: =$U$6*C3+$U$7 -> 1.9766537 | G3: =$U$10*A3+$U$11 -> -4.0796166 | H3: =TANH(G3) -> -0.999428 | I3: =$U$12*H3+$U$13 -> -1.0818197 | J3: =$U$14*H3+$U$15 -> -1.9082735 | K3: =$U$16*H3+$U$17 -> -2.0490121 | L3: =SUM(D3,I3) -> 1.0022603 | M3: =SUM(E3,J3) -> 0.068380263 | N3: =SUM(F3,K3) -> -0.072358419 | O3: 0.98960194 | P3: 0.0021639113 | Q3: 0.002694591 | R3: =SUM((L3-O3)^2, (M3-P3)^2, (N3-Q3)^2)/60 -> 0.00016962988 | T3: b11 | U3: 6.260022 | V3: 7.3372783
A4: 2 | B4: =$U$2*A4+$U$3 -> 5.4701352 | C4: =1/(1+EXP(-B4)) -> 0.99580699 | D4: =$U$4*C4+$U$5 -> 2.0827342 | E4: =$U$6*C4+$U$7 -> 1.9773292 | F4: =$U$6*C4+$U$7 -> 1.9773292 | G4: =$U$10*A4+$U$11 -> -3.953916 | H4: =TANH(G4) -> -0.99926457 | I4: =$U$12*H4+$U$13 -> -1.081821 | J4: =$U$14*H4+$U$15 -> -1.9083123 | K4: =$U$16*H4+$U$17 -> -2.0489721 | L4: =SUM(D4,I4) -> 1.0009132 | M4: =SUM(E4,J4) -> 0.069016882 | N4: =SUM(F4,K4) -> -0.071642962 | O4: 1.0027007 | P4: 0.0033100596 | Q4: -0.0047185297 | R4: =SUM((L4-O4)^2, (M4-P4)^2, (N4-Q4)^2)/60 -> 0.00014665769 | S4: Output for 1st | T4: w12S | U4: 0.98641727 | V4: 0.94514754
A5: 3 | B5: =$U$2*A5+$U$3 -> 5.0751918 | C5: =1/(1+EXP(-B5)) -> 0.99378893 | D5: =$U$4*C5+$U$5 -> 2.0807436 | E5: =$U$6*C5+$U$7 -> 1.9783283 | F5: =$U$6*C5+$U$7 -> 1.9783283 | G5: =$U$10*A5+$U$11 -> -3.8282154 | H5: =TANH(G5) -> -0.99905446 | I5: =$U$12*H5+$U$13 -> -1.0818228 | J5: =$U$14*H5+$U$15 -> -1.9083622 | K5: =$U$16*H5+$U$17 -> -2.0489207 | L5: =SUM(D5,I5) -> 0.99892073 | M5: =SUM(E5,J5) -> 0.069966127 | N5: =SUM(F5,K5) -> -0.070592365 | O5: 0.99110329 | P5: 0.0015165638 | Q5: 0.0024789689 | R5: =SUM((L5-O5)^2, (M5-P5)^2, (N5-Q5)^2)/60 -> 0.00016809791 | T5: b12S | U5: 1.100453 | V5: 0.02705399
A6: 4 | B6: =$U$2*A6+$U$3 -> 4.6802484 | C6: =1/(1+EXP(-B6)) -> 0.99080856 | D6: =$U$4*C6+$U$5 -> 2.0778037 | E6: =$U$6*C6+$U$7 -> 1.9798039 | F6: =$U$6*C6+$U$7 -> 1.9798039 | G6: =$U$10*A6+$U$11 -> -3.7025148 | H6: =TANH(G6) -> -0.99878437 | I6: =$U$12*H6+$U$13 -> -1.0818252 | J6: =$U$14*H6+$U$15 -> -1.9084263 | K6: =$U$16*H6+$U$17 -> -2.0488545 | L6: =SUM(D6,I6) -> 0.99597853 | M6: =SUM(E6,J6) -> 0.071377566 | N6: =SUM(F6,K6) -> -0.069050636 | O6: 0.99855053 | P6: 0.0020051112 | Q6: 0.0038636349 | R6: =SUM((L6-O6)^2, (M6-P6)^2, (N6-Q6)^2)/60 -> 0.00016892739 | T6: w12I | U6: -0.49509747 | V6: -0.44212351
A7: 5 | B7: =$U$2*A7+$U$3 -> 4.285305 | C7: =1/(1+EXP(-B7)) -> 0.9864176 | D7: =$U$4*C7+$U$5 -> 2.0734724 | E7: =$U$6*C7+$U$7 -> 1.9819778 | F7: =$U$6*C7+$U$7 -> 1.9819778 | G7: =$U$10*A7+$U$11 -> -3.5768143 | H7: =TANH(G7) -> -0.99843718 | I7: =$U$12*H7+$U$13 -> -1.0818281 | J7: =$U$14*H7+$U$15 -> -1.9085087 | K7: =$U$16*H7+$U$17 -> -2.0487695 | L7: =SUM(D7,I7) -> 0.99164425 | M7: =SUM(E7,J7) -> 0.073469074 | N7: =SUM(F7,K7) -> -0.066791649 | O7: 0.99334815 | P7: 0.0057859344 | Q7: -0.0046798608 | R7: =SUM((L7-O7)^2, (M7-P7)^2, (N7-Q7)^2)/60 -> 0.00014069642 | T7: b12I | U7: 2.4703507 | V7: -0.014636965
A8: 6 | B8: =$U$2*A8+$U$3 -> 3.8903616 | C8: =1/(1+EXP(-B8)) -> 0.97997139 | D8: =$U$4*C8+$U$5 -> 2.0671137 | E8: =$U$6*C8+$U$7 -> 1.9851693 | F8: =$U$6*C8+$U$7 -> 1.9851693 | G8: =$U$10*A8+$U$11 -> -3.4511137 | H8: =TANH(G8) -> -0.99799093 | I8: =$U$12*H8+$U$13 -> -1.0818319 | J8: =$U$14*H8+$U$15 -> -1.9086147 | K8: =$U$16*H8+$U$17 -> -2.0486602 | L8: =SUM(D8,I8) -> 0.98528178 | M8: =SUM(E8,J8) -> 0.076554611 | N8: =SUM(F8,K8) -> -0.063490849 | O8: 0.98283074 | P8: 0.012651331 | Q8: 0.0030346095 | R8: =SUM((L8-O8)^2, (M8-P8)^2, (N8-Q8)^2)/60 -> 0.00014192122 | T8: w12R | U8: -8.2452273 | V8: -0.065841424
A9: 7 | B9: =$U$2*A9+$U$3 -> 3.4954182 | C9: =1/(1+EXP(-B9)) -> 0.97055712 | D9: =$U$4*C9+$U$5 -> 2.0578273 | E9: =$U$6*C9+$U$7 -> 1.9898303 | F9: =$U$6*C9+$U$7 -> 1.9898303 | G9: =$U$10*A9+$U$11 -> -3.3254131 | H9: =TANH(G9) -> -0.99741743 | I9: =$U$12*H9+$U$13 -> -1.0818368 | J9: =$U$14*H9+$U$15 -> -1.9087509 | K9: =$U$16*H9+$U$17 -> -2.0485197 | L9: =SUM(D9,I9) -> 0.97599048 | M9: =SUM(E9,J9) -> 0.081079408 | N9: =SUM(F9,K9) -> -0.058689403 | O9: 0.97539399 | P9: 0.020354 | Q9: 0.007466831 | R9: =SUM((L9-O9)^2, (M9-P9)^2, (N9-Q9)^2)/60 -> 0.00013440964 | T9: b12R | U9: -5.0808451 | V9: 0.58028762
A10: 8 | B10: =$U$2*A10+$U$3 -> 3.1004747 | C10: =1/(1+EXP(-B10)) -> 0.95691232 | D10: =$U$4*C10+$U$5 -> 2.0443679 | E10: =$U$6*C10+$U$7 -> 1.9965858 | F10: =$U$6*C10+$U$7 -> 1.9965858 | G10: =$U$10*A10+$U$11 -> -3.1997126 | H10: =TANH(G10) -> -0.99668049 | I10: =$U$12*H10+$U$13 -> -1.0818431 | J10: =$U$14*H10+$U$15 -> -1.9089259 | K10: =$U$16*H10+$U$17 -> -2.0483392 | L10: =SUM(D10,I10) -> 0.96252472 | M10: =SUM(E10,J10) -> 0.087659918 | N10: =SUM(F10,K10) -> -0.051753404 | O10: 0.96249141 | P10: 0.033533967 | Q10: 0.0091761695 | R10: =SUM((L10-O10)^2, (M10-P10)^2, (N10-Q10)^2)/60 -> 0.00011070054 | S10: 2nd Neuron | T10: w21 | U10: 0.12570057 | V10: -0.13593674
A11: 9 | B11: =$U$2*A11+$U$3 -> 2.7055313 | C11: =1/(1+EXP(-B11)) -> 0.93735225 | D11: =$U$4*C11+$U$5 -> 2.0250735 | E11: =$U$6*C11+$U$7 -> 2.0062699 | F11: =$U$6*C11+$U$7 -> 2.0062699 | G11: =$U$10*A11+$U$11 -> -3.074012 | H11: =TANH(G11) -> -0.99573372 | I11: =$U$12*H11+$U$13 -> -1.0818512 | J11: =$U$14*H11+$U$15 -> -1.9091507 | K11: =$U$16*H11+$U$17 -> -2.0481073 | L11: =SUM(D11,I11) -> 0.94322223 | M11: =SUM(E11,J11) -> 0.09711924 | N11: =SUM(F11,K11) -> -0.041837369 | O11: 0.94450237 | P11: 0.047496166 | Q11: 0.007522534 | R11: =SUM((L11-O11)^2, (M11-P11)^2, (N11-Q11)^2)/60 -> 8.1674805e-05 | T11: b21 | U11: -4.2053171 | V11: 4.6279142
A12: 10 | B12: =$U$2*A12+$U$3 -> 2.3105879 | C12: =1/(1+EXP(-B12)) -> 0.90975014 | D12: =$U$4*C12+$U$5 -> 1.9978463 | E12: =$U$6*C12+$U$7 -> 2.0199357 | F12: =$U$6*C12+$U$7 -> 2.0199357 | G12: =$U$10*A12+$U$11 -> -2.9483114 | H12: =TANH(G12) -> -0.99451765 | I12: =$U$12*H12+$U$13 -> -1.0818616 | J12: =$U$14*H12+$U$15 -> -1.9094395 | K12: =$U$16*H12+$U$17 -> -2.0478095 | L12: =SUM(D12,I12) -> 0.91598464 | M12: =SUM(E12,J12) -> 0.11049621 | N12: =SUM(F12,K12) -> -0.027873788 | O12: 0.91819898 | P12: 0.067597221 | Q12: 0.0032927993 | R12: =SUM((L12-O12)^2, (M12-P12)^2, (N12-Q12)^2)/60 -> 4.6943039e-05 | S12: Output for 2nd | T12: w22S | U12: -0.0085469138 | V12: 0.011933844
A13: 11 | B13: =$U$2*A13+$U$3 -> 1.9156445 | C13: =1/(1+EXP(-B13)) -> 0.87165195 | D13: =$U$4*C13+$U$5 -> 1.9602655 | E13: =$U$6*C13+$U$7 -> 2.038798 | F13: =$U$6*C13+$U$7 -> 2.038798 | G13: =$U$10*A13+$U$11 -> -2.8226109 | H13: =TANH(G13) -> -0.99295617 | I13: =$U$12*H13+$U$13 -> -1.081875 | J13: =$U$14*H13+$U$15 -> -1.9098103 | K13: =$U$16*H13+$U$17 -> -2.047427 | L13: =SUM(D13,I13) -> 0.87839058 | M13: =SUM(E13,J13) -> 0.12898773 | N13: =SUM(F13,K13) -> -0.0086290262 | O13: 0.89021614 | P13: 0.095969398 | Q13: 0.019651499 | R13: =SUM((L13-O13)^2, (M13-P13)^2, (N13-Q13)^2)/60 -> 3.3830704e-05 | T13: b22S | U13: -1.0903617 | V13: -0.014264623
A14: 12 | B14: =$U$2*A14+$U$3 -> 1.5207011 | C14: =1/(1+EXP(-B14)) -> 0.8206417 | D14: =$U$4*C14+$U$5 -> 1.9099482 | E14: =$U$6*C14+$U$7 -> 2.064053 | F14: =$U$6*C14+$U$7 -> 2.064053 | G14: =$U$10*A14+$U$11 -> -2.6969103 | H14: =TANH(G14) -> -0.99095197 | I14: =$U$12*H14+$U$13 -> -1.0818921 | J14: =$U$14*H14+$U$15 -> -1.9102862 | K14: =$U$16*H14+$U$17 -> -2.0469361 | L14: =SUM(D14,I14) -> 0.82805606 | M14: =SUM(E14,J14) -> 0.15376686 | N14: =SUM(F14,K14) -> 0.017116902 | O14: 0.83105635 | P14: 0.13982037 | Q14: 0.024532806 | R14: =SUM((L14-O14)^2, (M14-P14)^2, (N14-Q14)^2)/60 -> 4.3083652e-06 | T14: w22I | U14: -0.23746059 | V14: 0.21749991
A15: 13 | B15: =$U$2*A15+$U$3 -> 1.1257577 | C15: =1/(1+EXP(-B15)) -> 0.75505514 | D15: =$U$4*C15+$U$5 -> 1.8452524 | E15: =$U$6*C15+$U$7 -> 2.0965248 | F15: =$U$6*C15+$U$7 -> 2.0965248 | G15: =$U$10*A15+$U$11 -> -2.5712097 | H15: =TANH(G15) -> -0.98838083 | I15: =$U$12*H15+$U$13 -> -1.0819141 | J15: =$U$14*H15+$U$15 -> -1.9108967 | K15: =$U$16*H15+$U$17 -> -2.0463064 | L15: =SUM(D15,I15) -> 0.76333837 | M15: =SUM(E15,J15) -> 0.18562805 | N15: =SUM(F15,K15) -> 0.050218375 | O15: 0.77338802 | P15: 0.1957633 | Q15: 0.038447975 | R15: =SUM((L15-O15)^2, (M15-P15)^2, (N15-Q15)^2)/60 -> 5.7043508e-06 | T15: b22I | U15: -2.1455982 | V15: 0.32240452
A16: 14 | B16: =$U$2*A16+$U$3 -> 0.73081427 | C16: =1/(1+EXP(-B16)) -> 0.67498393 | D16: =$U$4*C16+$U$5 -> 1.7662688 | E16: =$U$6*C16+$U$7 -> 2.1361678 | F16: =$U$6*C16+$U$7 -> 2.1361678 | G16: =$U$10*A16+$U$11 -> -2.4455092 | H16: =TANH(G16) -> -0.98508454 | I16: =$U$12*H16+$U$13 -> -1.0819422 | J16: =$U$14*H16+$U$15 -> -1.9116795 | K16: =$U$16*H16+$U$17 -> -2.0454991 | L16: =SUM(D16,I16) -> 0.68432657 | M16: =SUM(E16,J16) -> 0.22448837 | N16: =SUM(F16,K16) -> 0.090668776 | O16: 0.68790871 | P16: 0.25894601 | Q16: 0.063388111 | R16: =SUM((L16-O16)^2, (M16-P16)^2, (N16-Q16)^2)/60 -> 3.2406595e-05 | T16: w22R | U16: 0.2449257 | V16: -0.23429521
A17: 15 | B17: =$U$2*A17+$U$3 -> 0.33587085 | C17: =1/(1+EXP(-B17)) -> 0.58318716 | D17: =$U$4*C17+$U$5 -> 1.6757189 | E17: =$U$6*C17+$U$7 -> 2.1816162 | F17: =$U$6*C17+$U$7 -> 2.1816162 | G17: =$U$10*A17+$U$11 -> -2.3198086 | H17: =TANH(G17) -> -0.98086211 | I17: =$U$12*H17+$U$13 -> -1.0819783 | J17: =$U$14*H17+$U$15 -> -1.9126821 | K17: =$U$16*H17+$U$17 -> -2.0444649 | L17: =SUM(D17,I17) -> 0.59374056 | M17: =SUM(E17,J17) -> 0.26893406 | N17: =SUM(F17,K17) -> 0.13715131 | O17: 0.59497832 | P17: 0.33076846 | Q17: 0.073720662 | R17: =SUM((L17-O17)^2, (M17-P17)^2, (N17-Q17)^2)/60 -> 0.00013080786 | T17: b22R | U17: -1.8042265 | V17: 0.69072401
A18: 16 | B18: =$U$2*A18+$U$3 -> -0.059072558 | C18: =1/(1+EXP(-B18)) -> 0.48523615 | D18: =$U$4*C18+$U$5 -> 1.5790983 | E18: =$U$6*C18+$U$7 -> 2.2301115 | F18: =$U$6*C18+$U$7 -> 2.2301115 | G18: =$U$10*A18+$U$11 -> -2.194108 | H18: =TANH(G18) -> -0.97545912 | I18: =$U$12*H18+$U$13 -> -1.0820245 | J18: =$U$14*H18+$U$15 -> -1.9139651 | K18: =$U$16*H18+$U$17 -> -2.0431415 | L18: =SUM(D18,I18) -> 0.49707382 | M18: =SUM(E18,J18) -> 0.31614636 | N18: =SUM(F18,K18) -> 0.18696993 | O18: 0.48898601 | P18: 0.4078998 | Q18: 0.099755418 | R18: =SUM((L18-O18)^2, (M18-P18)^2, (N18-Q18)^2)/60 -> 0.00026817465 | V18: 0.068694641
A19: 17 | B19: =$U$2*A19+$U$3 -> -0.45401597 | C19: =1/(1+EXP(-B19)) -> 0.38840636 | D19: =$U$4*C19+$U$5 -> 1.4835838 | E19: =$U$6*C19+$U$7 -> 2.2780517 | F19: =$U$6*C19+$U$7 -> 2.2780517 | G19: =$U$10*A19+$U$11 -> -2.0684074 | H19: =TANH(G19) -> -0.96855499 | I19: =$U$12*H19+$U$13 -> -1.0820835 | J19: =$U$14*H19+$U$15 -> -1.9156046 | K19: =$U$16*H19+$U$17 -> -2.0414505 | L19: =SUM(D19,I19) -> 0.40150023 | M19: =SUM(E19,J19) -> 0.36244708 | N19: =SUM(F19,K19) -> 0.23660112 | O19: 0.39651124 | P19: 0.47372643 | Q19: 0.13353312 | R19: =SUM((L19-O19)^2, (M19-P19)^2, (N19-Q19)^2)/60 -> 0.00038384991 | V19: 0.44557095
A20: 18 | B20: =$U$2*A20+$U$3 -> -0.84895938 | C20: =1/(1+EXP(-B20)) -> 0.2996512 | D20: =$U$4*C20+$U$5 -> 1.3960341 | E20: =$U$6*C20+$U$7 -> 2.3219941 | F20: =$U$6*C20+$U$7 -> 2.3219941 | G20: =$U$10*A20+$U$11 -> -1.9427069 | H20: =TANH(G20) -> -0.95974809 | I20: =$U$12*H20+$U$13 -> -1.0821588 | J20: =$U$14*H20+$U$15 -> -1.9176959 | K20: =$U$16*H20+$U$17 -> -2.0392935 | L20: =SUM(D20,I20) -> 0.31387533 | M20: =SUM(E20,J20) -> 0.40429825 | N20: =SUM(F20,K20) -> 0.28270061 | O20: 0.31251276 | P20: 0.52750319 | Q20: 0.17173201 | R20: =SUM((L20-O20)^2, (M20-P20)^2, (N20-Q20)^2)/60 -> 0.00045825578
A21: 19 | B21: =$U$2*A21+$U$3 -> -1.2439028 | C21: =1/(1+EXP(-B21)) -> 0.22375738 | D21: =$U$4*C21+$U$5 -> 1.3211712 | E21: =$U$6*C21+$U$7 -> 2.359569 | F21: =$U$6*C21+$U$7 -> 2.359569 | G21: =$U$10*A21+$U$11 -> -1.8170063 | H21: =TANH(G21) -> -0.94853909 | I21: =$U$12*H21+$U$13 -> -1.0822546 | J21: =$U$14*H21+$U$15 -> -1.9203576 | K21: =$U$16*H21+$U$17 -> -2.0365481 | L21: =SUM(D21,I21) -> 0.23891656 | M21: =SUM(E21,J21) -> 0.43921139 | N21: =SUM(F21,K21) -> 0.32302082 | O21: 0.23552071 | P21: 0.55793615 | Q21: 0.20873749 | R21: =SUM((L21-O21)^2, (M21-P21)^2, (N21-Q21)^2)/60 -> 0.00045279634
A22: 20 | B22: =$U$2*A22+$U$3 -> -1.6388462 | C22: =1/(1+EXP(-B22)) -> 0.16262212 | D22: =$U$4*C22+$U$5 -> 1.2608663 | E22: =$U$6*C22+$U$7 -> 2.3898369 | F22: =$U$6*C22+$U$7 -> 2.3898369 | G22: =$U$10*A22+$U$11 -> -1.6913057 | H22: =TANH(G22) -> -0.93431332 | I22: =$U$12*H22+$U$13 -> -1.0823762 | J22: =$U$14*H22+$U$15 -> -1.9237356 | K22: =$U$16*H22+$U$17 -> -2.0330639 | L22: =SUM(D22,I22) -> 0.1784901 | M22: =SUM(E22,J22) -> 0.46610124 | N22: =SUM(F22,K22) -> 0.35677299 | O22: 0.18802497 | P22: 0.57727762 | Q22: 0.24586794 | R22: =SUM((L22-O22)^2, (M22-P22)^2, (N22-Q22)^2)/60 -> 0.0004125172
A23: 21 | B23: =$U$2*A23+$U$3 -> -2.0337896 | C23: =1/(1+EXP(-B23)) -> 0.11570063 | D23: =$U$4*C23+$U$5 -> 1.2145821 | E23: =$U$6*C23+$U$7 -> 2.4130676 | F23: =$U$6*C23+$U$7 -> 2.4130676 | G23: =$U$10*A23+$U$11 -> -1.5656052 | H23: =TANH(G23) -> -0.91632388 | I23: =$U$12*H23+$U$13 -> -1.0825299 | J23: =$U$14*H23+$U$15 -> -1.9280074 | K23: =$U$16*H23+$U$17 -> -2.0286578 | L23: =SUM(D23,I23) -> 0.13205217 | M23: =SUM(E23,J23) -> 0.48506017 | N23: =SUM(F23,K23) -> 0.38440978 | O23: 0.1379074 | P23: 0.57947853 | Q23: 0.28965693 | R23: =SUM((L23-O23)^2, (M23-P23)^2, (N23-Q23)^2)/60 -> 0.00029878686
A24: 22 | B24: =$U$2*A24+$U$3 -> -2.428733 | C24: =1/(1+EXP(-B24)) -> 0.081007737 | D24: =$U$4*C24+$U$5 -> 1.1803604 | E24: =$U$6*C24+$U$7 -> 2.4302439 | F24: =$U$6*C24+$U$7 -> 2.4302439 | G24: =$U$10*A24+$U$11 -> -1.4399046 | H24: =TANH(G24) -> -0.89367852 | I24: =$U$12*H24+$U$13 -> -1.0827235 | J24: =$U$14*H24+$U$15 -> -1.9333848 | K24: =$U$16*H24+$U$17 -> -2.0231114 | L24: =SUM(D24,I24) -> 0.097636957 | M24: =SUM(E24,J24) -> 0.49685915 | N24: =SUM(F24,K24) -> 0.40713257 | O24: 0.099076318 | P24: 0.57261055 | Q24: 0.33141839 | R24: =SUM((L24-O24)^2, (M24-P24)^2, (N24-Q24)^2)/60 -> 0.00019121641
A25: 23 | B25: =$U$2*A25+$U$3 -> -2.8236764 | C25: =1/(1+EXP(-B25)) -> 0.056058075 | D25: =$U$4*C25+$U$5 -> 1.1557497 | E25: =$U$6*C25+$U$7 -> 2.4425965 | F25: =$U$6*C25+$U$7 -> 2.4425965 | G25: =$U$10*A25+$U$11 -> -1.314204 | H25: =TANH(G25) -> -0.86533529 | I25: =$U$12*H25+$U$13 -> -1.0829657 | J25: =$U$14*H25+$U$15 -> -1.9401152 | K25: =$U$16*H25+$U$17 -> -2.0161694 | L25: =SUM(D25,I25) -> 0.072783932 | M25: =SUM(E25,J25) -> 0.50248126 | N25: =SUM(F25,K25) -> 0.42642707 | O25: 0.076771549 | P25: 0.55462506 | Q25: 0.37486334 | R25: =SUM((L25-O25)^2, (M25-P25)^2, (N25-Q25)^2)/60 -> 8.98949e-05 | AC25: beta | AD25: 0.5 | AE25: 0.44557095 | AF25: =ABS(AE25-AD25)/AD25 -> 0.10885809
A26: 24 | B26: =$U$2*A26+$U$3 -> -3.2186199 | C26: =1/(1+EXP(-B26)) -> 0.038471006 | D26: =$U$4*C26+$U$5 -> 1.1384015 | E26: =$U$6*C26+$U$7 -> 2.4513038 | F26: =$U$6*C26+$U$7 -> 2.4513038 | G26: =$U$10*A26+$U$11 -> -1.1885035 | H26: =TANH(G26) -> -0.83011415 | I26: =$U$12*H26+$U$13 -> -1.0832668 | J26: =$U$14*H26+$U$15 -> -1.9484788 | K26: =$U$16*H26+$U$17 -> -2.0075428 | L26: =SUM(D26,I26) -> 0.055134711 | M26: =SUM(E26,J26) -> 0.50282495 | N26: =SUM(F26,K26) -> 0.44376094 | O26: 0.055033185 | P26: 0.53385373 | Q26: 0.41205954 | R26: =SUM((L26-O26)^2, (M26-P26)^2, (N26-Q26)^2)/60 -> 3.2796243e-05
A27: 25 | B27: =$U$2*A27+$U$3 -> -3.6135633 | C27: =1/(1+EXP(-B27)) -> 0.026248092 | D27: =$U$4*C27+$U$5 -> 1.1263446 | E27: =$U$6*C27+$U$7 -> 2.4573553 | F27: =$U$6*C27+$U$7 -> 2.4573553 | G27: =$U$10*A27+$U$11 -> -1.0628029 | H27: =TANH(G27) -> -0.78673425 | I27: =$U$12*H27+$U$13 -> -1.0836375 | J27: =$U$14*H27+$U$15 -> -1.9587798 | K27: =$U$16*H27+$U$17 -> -1.996918 | L27: =SUM(D27,I27) -> 0.042707053 | M27: =SUM(E27,J27) -> 0.49857546 | N27: =SUM(F27,K27) -> 0.46043733 | O27: 0.041882891 | P27: 0.51004857 | Q27: 0.44388223 | R27: =SUM((L27-O27)^2, (M27-P27)^2, (N27-Q27)^2)/60 -> 6.773042e-06
A28: 26 | B28: =$U$2*A28+$U$3 -> -4.0085067 | C28: =1/(1+EXP(-B28)) -> 0.017836573 | D28: =$U$4*C28+$U$5 -> 1.1180473 | E28: =$U$6*C28+$U$7 -> 2.4615198 | F28: =$U$6*C28+$U$7 -> 2.4615198 | G28: =$U$10*A28+$U$11 -> -0.93710231 | H28: =TANH(G28) -> -0.73388808 | I28: =$U$12*H28+$U$13 -> -1.0840892 | J28: =$U$14*H28+$U$15 -> -1.9713287 | K28: =$U$16*H28+$U$17 -> -1.9839746 | L28: =SUM(D28,I28) -> 0.033958115 | M28: =SUM(E28,J28) -> 0.4901911 | N28: =SUM(F28,K28) -> 0.47754524 | O28: 0.026899077 | P28: 0.48054749 | Q28: 0.48772295 | R28: =SUM((L28-O28)^2, (M28-P28)^2, (N28-Q28)^2)/60 -> 4.1069207e-06
A29: 27 | B29: =$U$2*A29+$U$3 -> -4.4034501 | C29: =1/(1+EXP(-B29)) -> 0.012087168 | D29: =$U$4*C29+$U$5 -> 1.112376 | E29: =$U$6*C29+$U$7 -> 2.4643663 | F29: =$U$6*C29+$U$7 -> 2.4643663 | G29: =$U$10*A29+$U$11 -> -0.81140174 | H29: =TANH(G29) -> -0.6703628 | I29: =$U$12*H29+$U$13 -> -1.0846321 | J29: =$U$14*H29+$U$15 -> -1.9864135 | K29: =$U$16*H29+$U$17 -> -1.9684156 | L29: =SUM(D29,I29) -> 0.027743857 | M29: =SUM(E29,J29) -> 0.47795287 | N29: =SUM(F29,K29) -> 0.49595072 | O29: 0.028643067 | P29: 0.45621581 | Q29: 0.51359202 | R29: =SUM((L29-O29)^2, (M29-P29)^2, (N29-Q29)^2)/60 -> 1.3075392e-05
A30: 28 | B30: =$U$2*A30+$U$3 -> -4.7983935 | C30: =1/(1+EXP(-B30)) -> 0.0081755875 | D30: =$U$4*C30+$U$5 -> 1.1085176 | E30: =$U$6*C30+$U$7 -> 2.466303 | F30: =$U$6*C30+$U$7 -> 2.466303 | G30: =$U$10*A30+$U$11 -> -0.68570117 | H30: =TANH(G30) -> -0.59521326 | I30: =$U$12*H30+$U$13 -> -1.0852744 | J30: =$U$14*H30+$U$15 -> -2.0042585 | K30: =$U$16*H30+$U$17 -> -1.9500096 | L30: =SUM(D30,I30) -> 0.02324311 | M30: =SUM(E30,J30) -> 0.46204442 | N30: =SUM(F30,K30) -> 0.51629339 | O30: 0.018585383 | P30: 0.43462183 | Q30: 0.54771314 | R30: =SUM((L30-O30)^2, (M30-P30)^2, (N30-Q30)^2)/60 -> 2.9348233e-05
A31: 29 | B31: =$U$2*A31+$U$3 -> -5.1933369 | C31: =1/(1+EXP(-B31)) -> 0.0055227741 | D31: =$U$4*C31+$U$5 -> 1.1059008 | E31: =$U$6*C31+$U$7 -> 2.4676164 | F31: =$U$6*C31+$U$7 -> 2.4676164 | G31: =$U$10*A31+$U$11 -> -0.5600006 | H31: =TANH(G31) -> -0.50797788 | I31: =$U$12*H31+$U$13 -> -1.08602 | J31: =$U$14*H31+$U$15 -> -2.0249735 | K31: =$U$16*H31+$U$17 -> -1.9286434 | L31: =SUM(D31,I31) -> 0.019880735 | M31: =SUM(E31,J31) -> 0.44264286 | N31: =SUM(F31,K31) -> 0.53897298 | O31: 0.016441051 | P31: 0.40770547 | Q31: 0.57331042 | R31: =SUM((L31-O31)^2, (M31-P31)^2, (N31-Q31)^2)/60 -> 4.0191877e-05
A32: 30 | B32: =$U$2*A32+$U$3 -> -5.5882803 | C32: =1/(1+EXP(-B32)) -> 0.0037275101 | D32: =$U$4*C32+$U$5 -> 1.1041299 | E32: =$U$6*C32+$U$7 -> 2.4685052 | F32: =$U$6*C32+$U$7 -> 2.4685052 | G32: =$U$10*A32+$U$11 -> -0.43430003 | H32: =TANH(G32) -> -0.40890863 | I32: =$U$12*H32+$U$13 -> -1.0868668 | J32: =$U$14*H32+$U$15 -> -2.0484985 | K32: =$U$16*H32+$U$17 -> -1.9043788 | L32: =SUM(D32,I32) -> 0.01726312 | M32: =SUM(E32,J32) -> 0.42000665 | N32: =SUM(F32,K32) -> 0.56412641 | O32: 0.016927266 | P32: 0.38076373 | Q32: 0.60213874 | R32: =SUM((L32-O32)^2, (M32-P32)^2, (N32-Q32)^2)/60 -> 4.9750953e-05
A33: 31 | B33: =$U$2*A33+$U$3 -> -5.9832237 | C33: =1/(1+EXP(-B33)) -> 0.0025143493 | D33: =$U$4*C33+$U$5 -> 1.1029332 | E33: =$U$6*C33+$U$7 -> 2.4691058 | F33: =$U$6*C33+$U$7 -> 2.4691058 | G33: =$U$10*A33+$U$11 -> -0.30859946 | H33: =TANH(G33) -> -0.29916244 | I33: =$U$12*H33+$U$13 -> -1.0878048 | J33: =$U$14*H33+$U$15 -> -2.0745589 | K33: =$U$16*H33+$U$17 -> -1.8774991 | L33: =SUM(D33,I33) -> 0.015128446 | M33: =SUM(E33,J33) -> 0.39454689 | N33: =SUM(F33,K33) -> 0.59160671 | O33: 0.0055360201 | P33: 0.35516466 | Q33: 0.62492175 | R33: =SUM((L33-O33)^2, (M33-P33)^2, (N33-Q33)^2)/60 -> 4.5881115e-05
A34: 32 | B34: =$U$2*A34+$U$3 -> -6.3781672 | C34: =1/(1+EXP(-B34)) -> 0.0016953536 | D34: =$U$4*C34+$U$5 -> 1.1021253 | E34: =$U$6*C34+$U$7 -> 2.4695113 | F34: =$U$6*C34+$U$7 -> 2.4695113 | G34: =$U$10*A34+$U$11 -> -0.18289889 | H34: =TANH(G34) -> -0.18088637 | I34: =$U$12*H34+$U$13 -> -1.0888157 | J34: =$U$14*H34+$U$15 -> -2.1026448 | K34: =$U$16*H34+$U$17 -> -1.8485303 | L34: =SUM(D34,I34) -> 0.013309679 | M34: =SUM(E34,J34) -> 0.36686647 | N34: =SUM(F34,K34) -> 0.62098104 | O34: 0.0055516744 | P34: 0.33275256 | Q34: 0.65513191 | R34: =SUM((L34-O34)^2, (M34-P34)^2, (N34-Q34)^2)/60 -> 3.9837119e-05
A35: 33 | B35: =$U$2*A35+$U$3 -> -6.7731106 | C35: =1/(1+EXP(-B35)) -> 0.0011428227 | D35: =$U$4*C35+$U$5 -> 1.1015803 | E35: =$U$6*C35+$U$7 -> 2.4697849 | F35: =$U$6*C35+$U$7 -> 2.4697849 | G35: =$U$10*A35+$U$11 -> -0.057198323 | H35: =TANH(G35) -> -0.057136027 | I35: =$U$12*H35+$U$13 -> -1.0898733 | J35: =$U$14*H35+$U$15 -> -2.1320307 | K35: =$U$16*H35+$U$17 -> -1.8182206 | L35: =SUM(D35,I35) -> 0.011706969 | M35: =SUM(E35,J35) -> 0.33775419 | N35: =SUM(F35,K35) -> 0.65156424 | O35: 0.012931474 | P35: 0.31162242 | Q35: 0.68166378 | R35: =SUM((L35-O35)^2, (M35-P35)^2, (N35-Q35)^2)/60 -> 2.650586e-05
A36: 34 | B36: =$U$2*A36+$U$3 -> -7.168054 | C36: =1/(1+EXP(-B36)) -> 0.0007702276 | D36: =$U$4*C36+$U$5 -> 1.1012128 | E36: =$U$6*C36+$U$7 -> 2.4699693 | F36: =$U$6*C36+$U$7 -> 2.4699693 | G36: =$U$10*A36+$U$11 -> 0.068502247 | H36: =TANH(G36) -> 0.068395297 | I36: =$U$12*H36+$U$13 -> -1.0909462 | J36: =$U$14*H36+$U$15 -> -2.1618394 | K36: =$U$16*H36+$U$17 -> -1.7874748 | L36: =SUM(D36,I36) -> 0.01026653 | M36: =SUM(E36,J36) -> 0.30812992 | N36: =SUM(F36,K36) -> 0.68249455 | O36: 0.0086066662 | P36: 0.29035003 | Q36: 0.69814063 | R36: =SUM((L36-O36)^2, (M36-P36)^2, (N36-Q36)^2)/60 -> 9.3946561e-06
A37: 35 | B37: =$U$2*A37+$U$3 -> -7.5629974 | C37: =1/(1+EXP(-B37)) -> 0.00051904677 | D37: =$U$4*C37+$U$5 -> 1.100965 | E37: =$U$6*C37+$U$7 -> 2.4700937 | F37: =$U$6*C37+$U$7 -> 2.4700937 | G37: =$U$10*A37+$U$11 -> 0.19420282 | H37: =TANH(G37) -> 0.19179766 | I37: =$U$12*H37+$U$13 -> -1.092001 | J37: =$U$14*H37+$U$15 -> -2.1911426 | K37: =$U$16*H37+$U$17 -> -1.7572504 | L37: =SUM(D37,I37) -> 0.0089640512 | M37: =SUM(E37,J37) -> 0.27895108 | N37: =SUM(F37,K37) -> 0.71284332 | O37: 0.007357598 | P37: 0.27250954 | Q37: 0.71941412 | R37: =SUM((L37-O37)^2, (M37-P37)^2, (N37-Q37)^2)/60 -> 1.4541571e-06
... A61: 59 | B61: =$U$2*A61+$U$3 -> -17.041639 | C61: =1/(1+EXP(-B61)) -> 3.9710932e-08 | D61: =$U$4*C61+$U$5 -> 1.100453 | E61: =$U$6*C61+$U$7 -> 2.4703506 | F61: =$U$6*C61+$U$7 -> 2.4703506 | G61: =$U$10*A61+$U$11 -> 3.2110165 | H61: =TANH(G61) -> 0.99675458 | I61: =$U$12*H61+$U$13 -> -1.0988809 | J61: =$U$14*H61+$U$15 -> -2.3822882 | K61: =$U$16*H61+$U$17 -> -1.5600957 | L61: =SUM(D61,I61) -> 0.0015721962 | M61: =SUM(E61,J61) -> 0.088062496 | N61: =SUM(F61,K61) -> 0.91025492 | O61: -0.00010788248 | P61: 0.053596926 | Q61: 0.94100736 | R61: =SUM((L61-O61)^2, (M61-P61)^2, (N61-Q61)^2)/60 -> 3.5606851e-05

Sheet SIR_with 3 Neurons
A1: Day | B1: 1st Neuron | C1: ActFunc 1 | D1: f13S Predicted | E1: f13I Predicted | F1: f13R Predicted | G1: 2nd Neuron | H1: Act Fun 2 | I1: f23S Predicted | J1: f23I Predicted | K1: f23R Predicted | L1: 3rd Neuron | M1: Act Fun 3 | N1: f33S Predicted | O1: f33I Predicted | P1: f33R Predicted | Q1: S Pred | R1: I Pred | S1: R Pred | T1: S Real | U1: I Real | V1: R Real | W1: MSE | X1: Hidden Layer | Y1: Parameter | Z1: Value | AB1: MSE avg
A2: 0 | B2: =$Z$2*A2+$Z$3 -> -9.2993754 | C2: =1/(1+EXP(-B2)) -> 9.1472981e-05 | D2: =$Z$4*C2+$Z$5 -> -4.7912355 | E2: =$Z$6*C2+$Z$7 -> -2.2988216 | F2: =$Z$6*C2+$Z$7 -> -2.2988216 | G2: =$Z$10*A2+$Z$11 -> 1.7018717 | H2: =TANH(G2) -> 0.93564264 | I2: =$Z$12*H2+$Z$13 -> 6.1619041 | J2: =$Z$14*H2+$Z$15 -> -5.1253158 | K2: =$Z$16*H2+$Z$17 -> 5.8607233 | L2: =$Z$18*A2+$Z$19 -> 1.6548383 | M2: =TANH(L2) -> 0.92951857 | N2: =$Z$20*M2+$Z$21 -> -0.31531485 | O2: =$Z$22*M2+$Z$23 -> 7.4290104 | P2: =$Z$24*M2+$Z$25 -> -3.6191285 | Q2: =SUM(D2,I2,N2) -> 1.0553537 | R2: =SUM(E2,J2,O2) -> 0.0048729137 | S2: =SUM(F2,K2,P2) -> -0.057226901 | T2: 0.99916903 | U2: -0.00051644142 | V2: 0.0012964653 | W2: =SUM((Q2-T2)^2, (R2-U2)^2, (S2-V2)^2)/60 -> 0.0001101792 | X2: 1st Neuron | Y2: w11 | Z2: -7.1141902 | AA2: -7.1141902 | AB2: =AVERAGE(W2:W61) -> 4.4425913e-05
A3: 1 | B3: =$Z$2*A3+$Z$3 -> -16.413566 | C3: =1/(1+EXP(-B3)) -> 7.4418167e-08 | D3: =$Z$4*C3+$Z$5 -> -4.7908521 | E3: =$Z$6*C3+$Z$7 -> -2.2995974 | F3: =$Z$6*C3+$Z$7 -> -2.2995974 | G3: =$Z$10*A3+$Z$11 -> 1.6023899 | H3: =TANH(G3) -> 0.9220275 | I3: =$Z$12*H3+$Z$13 -> 6.1111805 | J3: =$Z$14*H3+$Z$15 -> -4.9935104 | K3: =$Z$16*H3+$Z$17 -> 5.7776979 | L3: =$Z$18*A3+$Z$19 -> 1.5603363 | M3: =TANH(L3) -> 0.91547492 | N3: =$Z$20*M3+$Z$21 -> -0.27042466 | O3: =$Z$22*M3+$Z$23 -> 7.2932748 | P3: =$Z$24*M3+$Z$25 -> -3.5262679 | Q3: =SUM(D3,I3,N3) -> 1.0499037 | R3: =SUM(E3,J3,O3) -> 0.00016692997 | S3: =SUM(F3,K3,P3) -> -0.048167404 | T3: 0.98960194 | U3: 0.0021639113 | V3: 0.002694591 | W3: =SUM((Q3-T3)^2, (R3-U3)^2, (S3-V3)^2)/60 -> 0.00010378718 | Y3: b11 | Z3: -9.2993754 | AA3: -9.2993754
A4: 2 | B4: =$Z$2*A4+$Z$3 -> -23.527756 | C4: =1/(1+EXP(-B4)) -> 6.0537633e-11 | D4: =$Z$4*C4+$Z$5 -> -4.7908518 | E4: =$Z$6*C4+$Z$7 -> -2.2995981 | F4: =$Z$6*C4+$Z$7 -> -2.2995981 | G4: =$Z$10*A4+$Z$11 -> 1.502908 | H4: =TANH(G4) -> 0.90567238 | I4: =$Z$12*H4+$Z$13 -> 6.050249 | J4: =$Z$14*H4+$Z$15 -> -4.8351797 | K4: =$Z$16*H4+$Z$17 -> 5.677964 | L4: =$Z$18*A4+$Z$19 -> 1.4658343 | M4: =TANH(L4) -> 0.89877981 | N4: =$Z$20*M4+$Z$21 -> -0.21705918 | O4: =$Z$22*M4+$Z$23 -> 7.1319123 | P4: =$Z$24*M4+$Z$25 -> -3.415875 | Q4: =SUM(D4,I4,N4) -> 1.042338 | R4: =SUM(E4,J4,O4) -> -0.0028655484 | S4: =SUM(F4,K4,P4) -> -0.037509063 | T4: 1.0027007 | U4: 0.0033100596 | V4: -0.0047185297 | W4: =SUM((Q4-T4)^2, (R4-U4)^2, (S4-V4)^2)/60 -> 4.4741203e-05 | X4: Output for 1st | Y4: w12S | Z4: -4.1942052 | AA4: -4.1942052
A5: 3 | B5: =$Z$2*A5+$Z$3 -> -30.641946 | C5: =1/(1+EXP(-B5)) -> 4.9246104e-14 | D5: =$Z$4*C5+$Z$5 -> -4.7908518 | E5: =$Z$6*C5+$Z$7 -> -2.2995981 | F5: =$Z$6*C5+$Z$7 -> -2.2995981 | G5: =$Z$10*A5+$Z$11 -> 1.4034262 | H5: =TANH(G5) -> 0.88608999 | I5: =$Z$12*H5+$Z$13 -> 5.9772942 | J5: =$Z$14*H5+$Z$15 -> -4.6456066 | K5: =$Z$16*H5+$Z$17 -> 5.5585503 | L5: =$Z$18*A5+$Z$19 -> 1.3713323 | M5: =TANH(L5) -> 0.87899546 | N5: =$Z$20*M5+$Z$21 -> -0.153819 | O5: =$Z$22*M5+$Z$23 -> 6.9406913 | P5: =$Z$24*M5+$Z$25 -> -3.2850552 | Q5: =SUM(D5,I5,N5) -> 1.0326234 | R5: =SUM(E5,J5,O5) -> -0.0045133451 | S5: =SUM(F5,K5,P5) -> -0.026102977 | T5: 0.99110329 | U5: 0.0015165638 | V5: 0.0024789689 | W5: =SUM((Q5-T5)^2, (R5-U5)^2, (S5-V5)^2)/60 -> 4.2953449e-05 | Y5: b12S | Z5: -4.7908518 | AA5: -4.7908518
A6: 4 | B6: =$Z$2*A6+$Z$3 -> -37.756136 | C6: =1/(1+EXP(-B6)) -> 4.006068e-17 | D6: =$Z$4*C6+$Z$5 -> -4.7908518 | E6: =$Z$6*C6+$Z$7 -> -2.2995981 | F6: =$Z$6*C6+$Z$7 -> -2.2995981 | G6: =$Z$10*A6+$Z$11 -> 1.3039444 | H6: =TANH(G6) -> 0.86273513 | I6: =$Z$12*H6+$Z$13 -> 5.890285 | J6: =$Z$14*H6+$Z$15 -> -4.4195129 | K6: =$Z$16*H6+$Z$17 -> 5.4161319 | L6: =$Z$18*A6+$Z$19 -> 1.2768303 | M6: =TANH(L6) -> 0.8556381 | N6: =$Z$20*M6+$Z$21 -> -0.079157763 | O6: =$Z$22*M6+$Z$23 -> 6.7149363 | P6: =$Z$24*M6+$Z$25 -> -3.1306095 | Q6: =SUM(D6,I6,N6) -> 1.0202754 | R6: =SUM(E6,J6,O6) -> -0.0041747001 | S6: =SUM(F6,K6,P6) -> -0.014075703 | T6: 0.99855053 | U6: 0.0020051112 | V6: 0.0038636349 | W6: =SUM((Q6-T6)^2, (R6-U6)^2, (S6-V6)^2)/60 -> 1.3866351e-05 | Y6: w12I | Z6: 8.4883201 | AA6: 8.4883201
A7: 5 | B7: =$Z$2*A7+$Z$3 -> -44.870327 | C7: =1/(1+EXP(-B7)) -> 3.2588529e-20 | D7: =$Z$4*C7+$Z$5 -> -4.7908518 | E7: =$Z$6*C7+$Z$7 -> -2.2995981 | F7: =$Z$6*C7+$Z$7 -> -2.2995981 | G7: =$Z$10*A7+$Z$11 -> 1.2044626 | H7: =TANH(G7) -> 0.83501073 | I7: =$Z$12*H7+$Z$13 -> 5.7869969 | J7: =$Z$14*H7+$Z$15 -> -4.1511185 | K7: =$Z$16*H7+$Z$17 -> 5.2470679 | L7: =$Z$18*A7+$Z$19 -> 1.1823283 | M7: =TANH(L7) -> 0.82818436 | N7: =$Z$20*M7+$Z$21 -> 0.0085974276 | O7: =$Z$22*M7+$Z$23 -> 6.4495887 | P7: =$Z$24*M7+$Z$25 -> -2.9490775 | Q7: =SUM(D7,I7,N7) -> 1.0047425 | R7: =SUM(E7,J7,O7) -> -0.0011278684 | S7: =SUM(F7,K7,P7) -> -0.0016076071 | T7: 0.99334815 | U7: 0.0057859344 | V7: -0.0046798608 | W7: =SUM((Q7-T7)^2, (R7-U7)^2, (S7-V7)^2)/60 -> 3.1178548e-06 | Y7: b12I | Z7: -2.2995981 | AA7: -2.2995981
A8: 6 | B8: =$Z$2*A8+$Z$3 -> -51.984517 | C8: =1/(1+EXP(-B8)) -> 2.6510089e-23 | D8: =$Z$4*C8+$Z$5 -> -4.7908518 | E8: =$Z$6*C8+$Z$7 -> -2.2995981 | F8: =$Z$6*C8+$Z$7 -> -2.2995981 | G8: =$Z$10*A8+$Z$11 -> 1.1049808 | H8: =TANH(G8) -> 0.802281 | I8: =$Z$12*H8+$Z$13 -> 5.6650613 | J8: =$Z$14*H8+$Z$15 -> -3.8342686 | K8: =$Z$16*H8+$Z$17 -> 5.0474814 | L8: =$Z$18*A8+$Z$19 -> 1.0878263 | M8: =TANH(L8) -> 0.79608339 | N8: =$Z$20*M8+$Z$21 -> 0.11120737 | O8: =$Z$22*M8+$Z$23 -> 6.1393245 | P8: =$Z$24*M8+$Z$25 -> -2.7368166 | Q8: =SUM(D8,I8,N8) -> 0.98541689 | R8: =SUM(E8,J8,O8) -> 0.0054578564 | S8: =SUM(F8,K8,P8) -> 0.011066722 | T8: 0.98283074 | U8: 0.012651331 | V8: 0.0030346095 | W8: =SUM((Q8-T8)^2, (R8-U8)^2, (S8-V8)^2)/60 -> 2.0491516e-06 | Y8: w12R | Z8: -2.6430285 | AA8: -2.6430285
A9: 7 | B9: =$Z$2*A9+$Z$3 -> -59.098707 | C9: =1/(1+EXP(-B9)) -> 2.1565405e-26 | D9: =$Z$4*C9+$Z$5 -> -4.7908518 | E9: =$Z$6*C9+$Z$7 -> -2.2995981 | F9: =$Z$6*C9+$Z$7 -> -2.2995981 | G9: =$Z$10*A9+$Z$11 -> 1.0054989 | H9: =TANH(G9) -> 0.76389391 | I9: =$Z$12*H9+$Z$13 -> 5.5220491 | J9: =$Z$14*H9+$Z$15 -> -3.462651 | K9: =$Z$16*H9+$Z$17 -> 4.8133962 | L9: =$Z$18*A9+$Z$19 -> 0.99332428 | M9: =TANH(L9) -> 0.75877624 | N9: =$Z$20*M9+$Z$21 -> 0.23045875 | O9: =$Z$22*M9+$Z$23 -> 5.7787411 | P9: =$Z$24*M9+$Z$25 -> -2.4901309 | Q9: =SUM(D9,I9,N9) -> 0.96165606 | R9: =SUM(E9,J9,O9) -> 0.016492115 | S9: =SUM(F9,K9,P9) -> 0.023667218 | T9: 0.97539399 | U9: 0.020354 | V9: 0.007466831 | W9: =SUM((Q9-T9)^2, (R9-U9)^2, (S9-V9)^2)/60 -> 7.768287e-06 | Y9: b12R | Z9: 1.1276781 | AA9: 1.1276781
A10: 8 | B10: =$Z$2*A10+$Z$3 -> -66.212897 | C10: =1/(1+EXP(-B10)) -> 1.7543008e-29 | D10: =$Z$4*C10+$Z$5 -> -4.7908518 | E10: =$Z$6*C10+$Z$7 -> -2.2995981 | F10: =$Z$6*C10+$Z$7 -> -2.2995981 | G10: =$Z$10*A10+$Z$11 -> 0.90601711 | H10: =TANH(G10) -> 0.71921509 | I10: =$Z$12*H10+$Z$13 -> 5.3555969 | J10: =$Z$14*H10+$Z$15 -> -3.0301243 | K10: =$Z$16*H10+$Z$17 -> 4.5409439 | L10: =$Z$18*A10+$Z$19 -> 0.89882228 | M10: =TANH(L10) -> 0.71572394 | N10: =$Z$20*M10+$Z$21 -> 0.36807437 | O10: =$Z$22*M10+$Z$23 -> 5.3626294 | P10: =$Z$24*M10+$Z$25 -> -2.2054566 | Q10: =SUM(D10,I10,N10) -> 0.93281944 | R10: =SUM(E10,J10,O10) -> 0.03290696 | S10: =SUM(F10,K10,P10) -> 0.035889223 | T10: 0.96249141 | U10: 0.033533967 | V10: 0.0091761695 | W10: =SUM((Q10-T10)^2, (R10-U10)^2, (S10-V10)^2)/60 -> 2.657343e-05 | X10: 2nd Neuron | Y10: w21 | Z10: -0.099481824 | AA10: -0.099481824
A11: 9 | B11: =$Z$2*A11+$Z$3 -> -73.327088 | C11: =1/(1+EXP(-B11)) -> 1.4270872e-32 | D11: =$Z$4*C11+$Z$5 -> -4.7908518 | E11: =$Z$6*C11+$Z$7 -> -2.2995981 | F11: =$Z$6*C11+$Z$7 -> -2.2995981 | G11: =$Z$10*A11+$Z$11 -> 0.80653528 | H11: =TANH(G11) -> 0.66767451 | I11: =$Z$12*H11+$Z$13 -> 5.1635809 | J11: =$Z$14*H11+$Z$15 -> -2.5311704 | K11: =$Z$16*H11+$Z$17 -> 4.2266485 | L11: =$Z$18*A11+$Z$19 -> 0.80432029 | M11: =TANH(L11) -> 0.66644512 | N11: =$Z$20*M11+$Z$21 -> 0.52559286 | O11: =$Z$22*M11+$Z$23 -> 4.8863368 | P11: =$Z$24*M11+$Z$25 -> -1.8796109 | Q11: =SUM(D11,I11,N11) -> 0.89832199 | R11: =SUM(E11,J11,O11) -> 0.055568344 | S11: =SUM(F11,K11,P11) -> 0.047439523 | T11: 0.94450237 | U11: 0.047496166 | V11: 0.007522534 | W11: =SUM((Q11-T11)^2, (R11-U11)^2, (S11-V11)^2)/60 -> 6.3185886e-05 | Y11: b21 | Z11: 1.7018717 | AA11: 1.7018717
A12: 10 | B12: =$Z$2*A12+$Z$3 -> -80.441278 | C12: =1/(1+EXP(-B12)) -> 1.1609057e-35 | D12: =$Z$4*C12+$Z$5 -> -4.7908518 | E12: =$Z$6*C12+$Z$7 -> -2.2995981 | F12: =$Z$6*C12+$Z$7 -> -2.2995981 | G12: =$Z$10*A12+$Z$11 -> 0.70705346 | H12: =TANH(G12) -> 0.60882581 | I12: =$Z$12*H12+$Z$13 -> 4.9443384 | J12: =$Z$14*H12+$Z$15 -> -1.9614679 | K12: =$Z$16*H12+$Z$17 -> 3.8677879 | L12: =$Z$18*A12+$Z$19 -> 0.70981829 | M12: =TANH(L12) -> 0.61056287 | N12: =$Z$20*M12+$Z$21 -> 0.70421908 | O12: =$Z$22*M12+$Z$23 -> 4.3462202 | P12: =$Z$24*M12+$Z$25 -> -1.5101013 | Q12: =SUM(D12,I12,N12) -> 0.85770563 | R12: =SUM(E12,J12,O12) -> 0.085154266 | S12: =SUM(F12,K12,P12) -> 0.058088575 | T12: 0.91819898 | U12: 0.067597221 | V12: 0.0032927993 | W12: =SUM((Q12-T12)^2, (R12-U12)^2, (S12-V12)^2)/60 -> 0.0001161712 | X12: Output for 2nd | Y12: w22S | Z12: 3.7255293 | AA12: 3.7255293
A13: 11 | B13: =$Z$2*A13+$Z$3 -> -87.555468 | C13: =1/(1+EXP(-B13)) -> 9.443726e-39 | D13: =$Z$4*C13+$Z$5 -> -4.7908518 | E13: =$Z$6*C13+$Z$7 -> -2.2995981 | F13: =$Z$6*C13+$Z$7 -> -2.2995981 | G13: =$Z$10*A13+$Z$11 -> 0.60757163 | H13: =TANH(G13) -> 0.54241545 | I13: =$Z$12*H13+$Z$13 -> 4.6969246 | J13: =$Z$14*H13+$Z$15 -> -1.3185626 | K13: =$Z$16*H13+$Z$17 -> 3.4628163 | L13: =$Z$18*A13+$Z$19 -> 0.61531629 | M13: =TANH(L13) -> 0.54785854 | N13: =$Z$20*M13+$Z$21 -> 0.90465191 | O13: =$Z$22*M13+$Z$23 -> 3.7401665 | P13: =$Z$24*M13+$Z$25 -> -1.0954821 | Q13: =SUM(D13,I13,N13) -> 0.81072473 | R13: =SUM(E13,J13,O13) -> 0.12200582 | S13: =SUM(F13,K13,P13) -> 0.067736102 | T13: 0.89021614 | U13: 0.095969398 | V13: 0.019651499 | W13: =SUM((Q13-T13)^2, (R13-U13)^2, (S13-V13)^2)/60 -> 0.00015514847 | Y13: b22S | Z13: 2.67614 | AA13: 2.67614
A14: 12 | B14: =$Z$2*A14+$Z$3 -> -94.669658 | C14: =1/(1+EXP(-B14)) -> 7.6822744e-42 | D14: =$Z$4*C14+$Z$5 -> -4.7908518 | E14: =$Z$6*C14+$Z$7 -> -2.2995981 | F14: =$Z$6*C14+$Z$7 -> -2.2995981 | G14: =$Z$10*A14+$Z$11 -> 0.50808981 | H14: =TANH(G14) -> 0.46845554 | I14: =$Z$12*H14+$Z$13 -> 4.4213848 | J14: =$Z$14*H14+$Z$15 -> -0.60257154 | K14: =$Z$16*H14+$Z$17 -> 3.0118073 | L14: =$Z$18*A14+$Z$19 -> 0.52081429 | M14: =TANH(L14) -> 0.47832824 | N14: =$Z$20*M14+$Z$21 -> 1.1269038 | O14: =$Z$22*M14+$Z$23 -> 3.0681379 | P14: =$Z$24*M14+$Z$25 -> -0.63572767 | Q14: =SUM(D14,I14,N14) -> 0.75743678 | R14: =SUM(E14,J14,O14) -> 0.16596832 | S14: =SUM(F14,K14,P14) -> 0.076481576 | T14: 0.83105635 | U14: 0.13982037 | V14: 0.024532806 | W14: =SUM((Q14-T14)^2, (R14-U14)^2, (S14-V14)^2)/60 -> 0.00014670385 | Y14: w22I | Z14: -9.6807986 | AA14: -9.6807986
A15: 13 | B15: =$Z$2*A15+$Z$3 -> -101.78385 | C15: =1/(1+EXP(-B15)) -> 6.2493702e-45 | D15: =$Z$4*C15+$Z$5 -> -4.7908518 | E15: =$Z$6*C15+$Z$7 -> -2.2995981 | F15: =$Z$6*C15+$Z$7 -> -2.2995981 | G15: =$Z$10*A15+$Z$11 -> 0.40860799 | H15: =TANH(G15) -> 0.3872901 | I15: =$Z$12*H15+$Z$13 -> 4.1190006 | J15: =$Z$14*H15+$Z$15 -> 0.18317473 | K15: =$Z$16*H15+$Z$17 -> 2.5168589 | L15: =$Z$18*A15+$Z$19 -> 0.42631229 | M15: =TANH(L15) -> 0.40223484 | N15: =$Z$20*M15+$Z$21 -> 1.3701344 | O15: =$Z$22*M15+$Z$23 -> 2.3326753 | P15: =$Z$24*M15+$Z$25 -> -0.13257611 | Q15: =SUM(D15,I15,N15) -> 0.69828322 | R15: =SUM(E15,J15,O15) -> 0.21625198 | S15: =SUM(F15,K15,P15) -> 0.084684737 | T15: 0.77338802 | U15: 0.1957633 | V15: 0.038447975 | W15: =SUM((Q15-T15)^2, (R15-U15)^2, (S15-V15)^2)/60 -> 0.00013663926 | Y15: b22I | Z15: 3.9324522 | AA15: 3.9324522
A16: 14 | B16: =$Z$2*A16+$Z$3 -> -108.89804 | C16: =1/(1+EXP(-B16)) -> 5.0837325e-48 | D16: =$Z$4*C16+$Z$5 -> -4.7908518 | E16: =$Z$6*C16+$Z$7 -> -2.2995981 | F16: =$Z$6*C16+$Z$7 -> -2.2995981 | G16: =$Z$10*A16+$Z$11 -> 0.30912616 | H16: =TANH(G16) -> 0.29964193 | I16: =$Z$12*H16+$Z$13 -> 3.7924647 | J16: =$Z$14*H16+$Z$15 -> 1.031679 | K16: =$Z$16*H16+$Z$17 -> 1.9823787 | L16: =$Z$18*A16+$Z$19 -> 0.3318103 | M16: =TANH(L16) -> 0.32014647 | N16: =$Z$20*M16+$Z$21 -> 1.6325279 | O16: =$Z$22*M16+$Z$23 -> 1.5392698 | P16: =$Z$24*M16+$Z$25 -> 0.41021592 | Q16: =SUM(D16,I16,N16) -> 0.63414081 | R16: =SUM(E16,J16,O16) -> 0.27135074 | S16: =SUM(F16,K16,P16) -> 0.09299653 | T16: 0.68790871 | U16: 0.25894601 | V16: 0.063388111 | W16: =SUM((Q16-T16)^2, (R16-U16)^2, (S16-V16)^2)/60 -> 6.5358716e-05 | Y16: w22R | Z16: 6.0980192 | AA16: 6.0980192
A17: 15 | B17: =$Z$2*A17+$Z$3 -> -116.01223 | C17: =1/(1+EXP(-B17)) -> 4.1355105e-51 | D17: =$Z$4*C17+$Z$5 -> -4.7908518 | E17: =$Z$6*C17+$Z$7 -> -2.2995981 | F17: =$Z$6*C17+$Z$7 -> -2.2995981 | G17: =$Z$10*A17+$Z$11 -> 0.20964434 | H17: =TANH(G17) -> 0.20662605 | I17: =$Z$12*H17+$Z$13 -> 3.4459314 | J17: =$Z$14*H17+$Z$15 -> 1.932147 | K17: =$Z$16*H17+$Z$17 -> 1.4151661 | L17: =$Z$18*A17+$Z$19 -> 0.2373083 | M17: =TANH(L17) -> 0.23295172 | N17: =$Z$20*M17+$Z$21 -> 1.9112437 | O17: =$Z$22*M17+$Z$23 -> 0.69650971 | P17: =$Z$24*M17+$Z$25 -> 0.98677282 | Q17: =SUM(D17,I17,N17) -> 0.56632328 | R17: =SUM(E17,J17,O17) -> 0.32905866 | S17: =SUM(F17,K17,P17) -> 0.10234082 | T17: 0.59497832 | U17: 0.33076846 | V17: 0.073720662 | W17: =SUM((Q17-T17)^2, (R17-U17)^2, (S17-V17)^2)/60 -> 2.7385805e-05 | Y17: b22R | Z17: 0.15515646 | AA17: 0.15515646
A18: 16 | B18: =$Z$2*A18+$Z$3 -> -123.12642 | C18: =1/(1+EXP(-B18)) -> 3.3641517e-54 | D18: =$Z$4*C18+$Z$5 -> -4.7908518 | E18: =$Z$6*C18+$Z$7 -> -2.2995981 | F18: =$Z$6*C18+$Z$7 -> -2.2995981 | G18: =$Z$10*A18+$Z$11 -> 0.11016251 | H18: =TANH(G18) -> 0.10971903 | I18: =$Z$12*H18+$Z$13 -> 3.0849014 | J18: =$Z$14*H18+$Z$15 -> 2.8702843 | K18: =$Z$16*H18+$Z$17 -> 0.82422522 | L18: =$Z$18*A18+$Z$19 -> 0.1428063 | M18: =TANH(L18) -> 0.14184337 | N18: =$Z$20*M18+$Z$21 -> 2.2024693 | O18: =$Z$22*M18+$Z$23 -> -0.18407625 | P18: =$Z$24*M18+$Z$25 -> 1.5892075 | Q18: =SUM(D18,I18,N18) -> 0.49651889 | R18: =SUM(E18,J18,O18) -> 0.38661002 | S18: =SUM(F18,K18,P18) -> 0.11383468 | T18: 0.48898601 | U18: 0.4078998 | V18: 0.099755418 | W18: =SUM((Q18-T18)^2, (R18-U18)^2, (S18-V18)^2)/60 -> 1.1803744e-05 | X18: 3rd Neuron | Y18: w31 | Z18: -0.094501998 | AA18: -0.094501998
A19: 17 | B19: =$Z$2*A19+$Z$3 -> -130.24061 | C19: =1/(1+EXP(-B19)) -> 2.7366673e-57 | D19: =$Z$4*C19+$Z$5 -> -4.7908518 | E19: =$Z$6*C19+$Z$7 -> -2.2995981 | F19: =$Z$6*C19+$Z$7 -> -2.2995981 | G19: =$Z$10*A19+$Z$11 -> 0.01068069 | H19: =TANH(G19) -> 0.010680284 | I19: =$Z$12*H19+$Z$13 -> 2.7159297 | J19: =$Z$14*H19+$Z$15 -> 3.8290585 | K19: =$Z$16*H19+$Z$17 -> 0.22028504 | L19: =$Z$18*A19+$Z$19 -> 0.048304301 | M19: =TANH(L19) -> 0.048266766 | N19: =$Z$20*M19+$Z$21 -> 2.5015846 | O19: =$Z$22*M19+$Z$23 -> -1.0885186 | P19: =$Z$24*M19+$Z$25 -> 2.2079631 | Q19: =SUM(D19,I19,N19) -> 0.42666243 | R19: =SUM(E19,J19,O19) -> 0.44094183 | S19: =SUM(F19,K19,P19) -> 0.12865007 | T19: 0.39651124 | U19: 0.47372643 | V19: 0.13353312 | W19: =SUM((Q19-T19)^2, (R19-U19)^2, (S19-V19)^2)/60 -> 3.3462811e-05 | Y19: b31 | Z19: 1.6548383 | AA19: 1.6548383
A20: 18 | B20: =$Z$2*A20+$Z$3 -> -137.3548 | C20: =1/(1+EXP(-B20)) -> 2.2262219e-60 | D20: =$Z$4*C20+$Z$5 -> -4.7908518 | E20: =$Z$6*C20+$Z$7 -> -2.2995981 | F20: =$Z$6*C20+$Z$7 -> -2.2995981 | G20: =$Z$10*A20+$Z$11 -> -0.088801134 | H20: =TANH(G20) -> -0.08856845 | I20: =$Z$12*H20+$Z$13 -> 2.3461756 | J20: =$Z$14*H20+$Z$15 -> 4.7898655 | K20: =$Z$16*H20+$Z$17 -> -0.38493565 | L20: =$Z$18*A20+$Z$19 -> -0.046197697 | M20: =TANH(L20) -> -0.04616486 | N20: =$Z$20*M20+$Z$21 -> 2.8034329 | O20: =$Z$22*M20+$Z$23 -> -2.001225 | P20: =$Z$24*M20+$Z$25 -> 2.8323723 | Q20: =SUM(D20,I20,N20) -> 0.3587567 | R20: =SUM(E20,J20,O20) -> 0.48904249 | S20: =SUM(F20,K20,P20) -> 0.14783859 | T20: 0.31251276 | U20: 0.52750319 | V20: 0.17173201 | W20: =SUM((Q20-T20)^2, (R20-U20)^2, (S20-V20)^2)/60 -> 6.981039e-05 | X20: Output for 3rd | Y20: w32S | Z20: -3.196475 | AA20: -3.196475
A21: 19 | B21: =$Z$2*A21+$Z$3 -> -144.46899 | C21: =1/(1+EXP(-B21)) -> 1.8109851e-63 | D21: =$Z$4*C21+$Z$5 -> -4.7908518 | E21: =$Z$6*C21+$Z$7 -> -2.2995981 | F21: =$Z$6*C21+$Z$7 -> -2.2995981 | G21: =$Z$10*A21+$Z$11 -> -0.18828296 | H21: =TANH(G21) -> -0.18608915 | I21: =$Z$12*H21+$Z$13 -> 1.9828594 | J21: =$Z$14*H21+$Z$15 -> 5.7339438 | K21: =$Z$16*H21+$Z$17 -> -0.97961878 | L21: =$Z$18*A21+$Z$19 -> -0.1406997 | M21: =TANH(L21) -> -0.13977854 | N21: =$Z$20*M21+$Z$21 -> 3.1026667 | O21: =$Z$22*M21+$Z$23 -> -2.9060256 | P21: =$Z$24*M21+$Z$25 -> 3.451373 | Q21: =SUM(D21,I21,N21) -> 0.29467425 | R21: =SUM(E21,J21,O21) -> 0.52832012 | S21: =SUM(F21,K21,P21) -> 0.17215617 | T21: 0.23552071 | U21: 0.55793615 | V21: 0.20873749 | W21: =SUM((Q21-T21)^2, (R21-U21)^2, (S21-V21)^2)/60 -> 9.5240721e-05 | Y21: b32S | Z21: 2.6558681 | AA21: 2.6558681
A22: 20 | B22: =$Z$2*A22+$Z$3 -> -151.58318 | C22: =1/(1+EXP(-B22)) -> 1.4731987e-66 | D22: =$Z$4*C22+$Z$5 -> -4.7908518 | E22: =$Z$6*C22+$Z$7 -> -2.2995981 | F22: =$Z$6*C22+$Z$7 -> -2.2995981 | G22: =$Z$10*A22+$Z$11 -> -0.28776478 | H22: =TANH(G22) -> -0.28007622 | I22: =$Z$12*H22+$Z$13 -> 1.6327078 | J22: =$Z$14*H22+$Z$15 -> 6.6438137 | K22: =$Z$16*H22+$Z$17 -> -1.5527537 | L22: =$Z$18*A22+$Z$19 -> -0.23520169 | M22: =TANH(L22) -> -0.23095846 | N22: =$Z$20*M22+$Z$21 -> 3.394121 | O22: =$Z$22*M22+$Z$23 -> -3.7873034 | P22: =$Z$24*M22+$Z$25 -> 4.054281 | Q22: =SUM(D22,I22,N22) -> 0.235977 | R22: =SUM(E22,J22,O22) -> 0.55691228 | S22: =SUM(F22,K22,P22) -> 0.20192919 | T22: 0.18802497 | U22: 0.57727762 | V22: 0.24586794 | W22: =SUM((Q22-T22)^2, (R22-U22)^2, (S22-V22)^2)/60 -> 7.741263e-05 | Y22: w32I | Z22: 9.6652613 | AA22: 9.6652613
A23: 21 | B23: =$Z$2*A23+$Z$3 -> -158.69737 | C23: =1/(1+EXP(-B23)) -> 1.1984164e-69 | D23: =$Z$4*C23+$Z$5 -> -4.7908518 | E23: =$Z$6*C23+$Z$7 -> -2.2995981 | F23: =$Z$6*C23+$Z$7 -> -2.2995981 | G23: =$Z$10*A23+$Z$11 -> -0.38724661 | H23: =TANH(G23) -> -0.36898413 | I23: =$Z$12*H23+$Z$13 -> 1.3014788 | J23: =$Z$14*H23+$Z$15 -> 7.5045132 | K23: =$Z$16*H23+$Z$17 -> -2.0949158 | L23: =$Z$18*A23+$Z$19 -> -0.32970369 | M23: =TANH(L23) -> -0.31825451 | N23: =$Z$20*M23+$Z$21 -> 3.6731607 | O23: =$Z$22*M23+$Z$23 -> -4.6310425 | P23: =$Z$24*M23+$Z$25 -> 4.6315077 | Q23: =SUM(D23,I23,N23) -> 0.18378764 | R23: =SUM(E23,J23,O23) -> 0.57387266 | S23: =SUM(F23,K23,P23) -> 0.23699379 | T23: 0.1379074 | U23: 0.57947853 | V23: 0.28965693 | W23: =SUM((Q23-T23)^2, (R23-U23)^2, (S23-V23)^2)/60 -> 8.1830475e-05 | Y23: b32I | Z23: -1.5550295 | AA23: -1.5550295
A24: 22 | B24: =$Z$2*A24+$Z$3 -> -165.81156 | C24: =1/(1+EXP(-B24)) -> 9.748868e-73 | D24: =$Z$4*C24+$Z$5 -> -4.7908518 | E24: =$Z$6*C24+$Z$7 -> -2.2995981 | F24: =$Z$6*C24+$Z$7 -> -2.2995981 | G24: =$Z$10*A24+$Z$11 -> -0.48672843 | H24: =TANH(G24) -> -0.45161597 | I24: =$Z$12*H24+$Z$13 -> 0.99363143 | J24: =$Z$14*H24+$Z$15 -> 8.3044555 | K24: =$Z$16*H24+$Z$17 -> -2.5988064 | L24: =$Z$18*A24+$Z$19 -> -0.42420569 | M24: =TANH(L24) -> -0.40046757 | N24: =$Z$20*M24+$Z$21 -> 3.9359527 | O24: =$Z$22*M24+$Z$23 -> -5.4256533 | P24: =$Z$24*M24+$Z$25 -> 5.1751243 | Q24: =SUM(D24,I24,N24) -> 0.13873229 | R24: =SUM(E24,J24,O24) -> 0.57920414 | S24: =SUM(F24,K24,P24) -> 0.27671978 | T24: 0.099076318 | U24: 0.57261055 | V24: 0.33141839 | W24: =SUM((Q24-T24)^2, (R24-U24)^2, (S24-V24)^2)/60 -> 7.6800165e-05 | Y24: w32R | Z24: -6.612289 | AA24: -6.612289
A25: 23 | B25: =$Z$2*A25+$Z$3 -> -172.92575 | C25: =1/(1+EXP(-B25)) -> 7.9305011e-76 | D25: =$Z$4*C25+$Z$5 -> -4.7908518 | E25: =$Z$6*C25+$Z$7 -> -2.2995981 | F25: =$Z$6*C25+$Z$7 -> -2.2995981 | G25: =$Z$10*A25+$Z$11 -> -0.58621025 | H25: =TANH(G25) -> -0.52716451 | I25: =$Z$12*H25+$Z$13 -> 0.71217314 | J25: =$Z$14*H25+$Z$15 -> 9.0358257 | K25: =$Z$16*H25+$Z$17 -> -3.0595028 | L25: =$Z$18*A25+$Z$19 -> -0.51870769 | M25: =TANH(L25) -> -0.47670199 | N25: =$Z$20*M25+$Z$21 -> 4.1796341 | O25: =$Z$22*M25+$Z$23 -> -6.1624788 | P25: =$Z$24*M25+$Z$25 -> 5.6792082 | Q25: =SUM(D25,I25,N25) -> 0.1009554 | R25: =SUM(E25,J25,O25) -> 0.5737488 | S25: =SUM(F25,K25,P25) -> 0.32010732 | T25: 0.076771549 | U25: 0.55462506 | V25: 0.37486334 | W25: =SUM((Q25-T25)^2, (R25-U25)^2, (S25-V25)^2)/60 -> 6.5813302e-05 | Y25: b32R | Z25: 2.5271169 | AA25: 2.5271169
A26: 24 | B26: =$Z$2*A26+$Z$3 -> -180.03994 | C26: =1/(1+EXP(-B26)) -> 6.4512975e-79 | D26: =$Z$4*C26+$Z$5 -> -4.7908518 | E26: =$Z$6*C26+$Z$7 -> -2.2995981 | F26: =$Z$6*C26+$Z$7 -> -2.2995981 | G26: =$Z$10*A26+$Z$11 -> -0.68569208 | H26: =TANH(G26) -> -0.59520739 | I26: =$Z$12*H26+$Z$13 -> 0.45867742 | J26: =$Z$14*H26+$Z$15 -> 9.694535 | K26: =$Z$16*H26+$Z$17 -> -3.4744296 | L26: =$Z$18*A26+$Z$19 -> -0.61320969 | M26: =TANH(L26) -> -0.54638253 | N26: =$Z$20*M26+$Z$21 -> 4.4023662 | O26: =$Z$22*M26+$Z$23 -> -6.8359595 | P26: =$Z$24*M26+$Z$25 -> 6.1399561 | Q26: =SUM(D26,I26,N26) -> 0.070191806 | R26: =SUM(E26,J26,O26) -> 0.55897748 | S26: =SUM(F26,K26,P26) -> 0.36592847 | T26: 0.055033185 | U26: 0.53385373 | V26: 0.41205954 | W26: =SUM((Q26-T26)^2, (R26-U26)^2, (S26-V26)^2)/60 -> 4.9817708e-05 | AA26: 0.066692555
A27: 25 | B27: =$Z$2*A27+$Z$3 -> -187.15413 | C27: =1/(1+EXP(-B27)) -> 5.2479961e-82 | D27: =$Z$4*C27+$Z$5 -> -4.7908518 | E27: =$Z$6*C27+$Z$7 -> -2.2995981 | F27: =$Z$6*C27+$Z$7 -> -2.2995981 | G27: =$Z$10*A27+$Z$11 -> -0.7851739 | H27: =TANH(G27) -> -0.65566637 | I27: =$Z$12*H27+$Z$13 -> 0.2334357 | J27: =$Z$14*H27+$Z$15 -> 10.279826 | K27: =$Z$16*H27+$Z$17 -> -3.8431097 | L27: =$Z$18*A27+$Z$19 -> -0.70771168 | M27: =TANH(L27) -> -0.60923988 | N27: =$Z$20*M27+$Z$21 -> 4.6032882 | O27: =$Z$22*M27+$Z$23 -> -7.4434922 | P27: =$Z$24*M27+$Z$25 -> 6.5555871 | Q27: =SUM(D27,I27,N27) -> 0.045872045 | R27: =SUM(E27,J27,O27) -> 0.536736 | S27: =SUM(F27,K27,P27) -> 0.4128794 | T27: 0.041882891 | U27: 0.51004857 | V27: 0.44388223 | W27: =SUM((Q27-T27)^2, (R27-U27)^2, (S27-V27)^2)/60 -> 2.8155135e-05 | AA27: 0.43871612
A28: 26 | B28: =$Z$2*A28+$Z$3 -> -194.26832 | C28: =1/(1+EXP(-B28)) -> 4.2691355e-85 | D28: =$Z$4*C28+$Z$5 -> -4.7908518 | E28: =$Z$6*C28+$Z$7 -> -2.2995981 | F28: =$Z$6*C28+$Z$7 -> -2.2995981 | G28: =$Z$10*A28+$Z$11 -> -0.88465573 | H28: =TANH(G28) -> -0.70874404 | I28: =$Z$12*H28+$Z$13 -> 0.035693265 | J28: =$Z$14*H28+$Z$15 -> 10.793661 | K28: =$Z$16*H28+$Z$17 -> -4.1667783 | L28: =$Z$18*A28+$Z$19 -> -0.80221368 | M28: =TANH(L28) -> -0.66527252 | N28: =$Z$20*M28+$Z$21 -> 4.7823951 | O28: =$Z$22*M28+$Z$23 -> -7.9850623 | P28: =$Z$24*M28+$Z$25 -> 6.9260911 | Q28: =SUM(D28,I28,N28) -> 0.027236539 | R28: =SUM(E28,J28,O28) -> 0.5090002 | S28: =SUM(F28,K28,P28) -> 0.45971472 | T28: 0.026899077 | U28: 0.48054749 | V28: 0.48772295 | W28: =SUM((Q28-T28)^2, (R28-U28)^2, (S28-V28)^2)/60 -> 2.6568872e-05
A29: 27 | B29: =$Z$2*A29+$Z$3 -> -201.38251 | C29: =1/(1+EXP(-B29)) -> 3.4728528e-88 | D29: =$Z$4*C29+$Z$5 -> -4.7908518 | E29: =$Z$6*C29+$Z$7 -> -2.2995981 | F29: =$Z$6*C29+$Z$7 -> -2.2995981 | G29: =$Z$10*A29+$Z$11 -> -0.98413755 | H29: =TANH(G29) -> -0.75485144 | I29: =$Z$12*H29+$Z$13 -> -0.1360812 | J29: =$Z$14*H29+$Z$15 -> 11.240017 | K29: =$Z$16*H29+$Z$17 -> -4.4479421 | L29: =$Z$18*A29+$Z$19 -> -0.89671568 | M29: =TANH(L29) -> -0.71469491 | N29: =$Z$20*M29+$Z$21 -> 4.9403725 | O29: =$Z$22*M29+$Z$23 -> -8.4627426 | P29: =$Z$24*M29+$Z$25 -> 7.2528862 | Q29: =SUM(D29,I29,N29) -> 0.013439516 | R29: =SUM(E29,J29,O29) -> 0.47767632 | S29: =SUM(F29,K29,P29) -> 0.50534605 | T29: 0.028643067 | U29: 0.45621581 | V29: 0.51359202 | W29: =SUM((Q29-T29)^2, (R29-U29)^2, (S29-V29)^2)/60 -> 1.266162e-05
A30: 28 | B30: =$Z$2*A30+$Z$3 -> -208.4967 | C30: =1/(1+EXP(-B30)) -> 2.8250934e-91 | D30: =$Z$4*C30+$Z$5 -> -4.7908518 | E30: =$Z$6*C30+$Z$7 -> -2.2995981 | F30: =$Z$6*C30+$Z$7 -> -2.2995981 | G30: =$Z$10*A30+$Z$11 -> -1.0836194 | H30: =TANH(G30) -> -0.79453744 | I30: =$Z$12*H30+$Z$13 -> -0.28393254 | J30: =$Z$14*H30+$Z$15 -> 11.624209 | K30: =$Z$16*H30+$Z$17 -> -4.6899481 | L30: =$Z$18*A30+$Z$19 -> -0.99121768 | M30: =TANH(L30) -> -0.75788107 | N30: =$Z$20*M30+$Z$21 -> 5.078416 | O30: =$Z$22*M30+$Z$23 -> -8.8801481 | P30: =$Z$24*M30+$Z$25 -> 7.5384456 | Q30: =SUM(D30,I30,N30) -> 0.0036316305 | R30: =SUM(E30,J30,O30) -> 0.44446301 | S30: =SUM(F30,K30,P30) -> 0.54889941 | T30: 0.018585383 | U30: 0.43462183 | V30: 0.54771314 | W30: =SUM((Q30-T30)^2, (R30-U30)^2, (S30-V30)^2)/60 -> 5.3645125e-06
A31: 29 | B31: =$Z$2*A31+$Z$3 -> -215.61089 | C31: =1/(1+EXP(-B31)) -> 2.2981547e-94 | D31: =$Z$4*C31+$Z$5 -> -4.7908518 | E31: =$Z$6*C31+$Z$7 -> -2.2995981 | F31: =$Z$6*C31+$Z$7 -> -2.2995981 | G31: =$Z$10*A31+$Z$11 -> -1.1831012 | H31: =TANH(G31) -> -0.82842699 | I31: =$Z$12*H31+$Z$13 -> -0.41018904 | J31: =$Z$14*H31+$Z$15 -> 11.952287 | K31: =$Z$16*H31+$Z$17 -> -4.8966072 | L31: =$Z$18*A31+$Z$19 -> -1.0857197 | M31: =TANH(L31) -> -0.79531055 | N31: =$Z$20*M31+$Z$21 -> 5.1980584 | O31: =$Z$22*M31+$Z$23 -> -9.2419138 | P31: =$Z$24*M31+$Z$25 -> 7.7859402 | Q31: =SUM(D31,I31,N31) -> -0.0029824511 | R31: =SUM(E31,J31,O31) -> 0.41077512 | S31: =SUM(F31,K31,P31) -> 0.58973488 | T31: 0.016441051 | U31: 0.40770547 | V31: 0.57331042 | W31: =SUM((Q31-T31)^2, (R31-U31)^2, (S31-V31)^2)/60 -> 1.0940969e-05
A32: 30 | B32: =$Z$2*A32+$Z$3 -> -222.72508 | C32: =1/(1+EXP(-B32)) -> 1.869501e-97 | D32: =$Z$4*C32+$Z$5 -> -4.7908518 | E32: =$Z$6*C32+$Z$7 -> -2.2995981 | F32: =$Z$6*C32+$Z$7 -> -2.2995981 | G32: =$Z$10*A32+$Z$11 -> -1.282583 | H32: =TANH(G32) -> -0.8571716 | I32: =$Z$12*H32+$Z$13 -> -0.51727794 | J32: =$Z$14*H32+$Z$15 -> 12.230558 | K32: =$Z$16*H32+$Z$17 -> -5.0718924 | L32: =$Z$18*A32+$Z$19 -> -1.1802217 | M32: =TANH(L32) -> -0.8275215 | N32: =$Z$20*M32+$Z$21 -> 5.3010199 | O32: =$Z$22*M32+$Z$23 -> -9.553241 | P32: =$Z$24*M32+$Z$25 -> 7.9989282 | Q32: =SUM(D32,I32,N32) -> -0.0071098625 | R32: =SUM(E32,J32,O32) -> 0.37771872 | S32: =SUM(F32,K32,P32) -> 0.62743776 | T32: 0.016927266 | U32: 0.38076373 | V32: 0.60213874 | W32: =SUM((Q32-T32)^2, (R32-U32)^2, (S32-V32)^2)/60 -> 2.04516e-05
